Workbook

Sheet Inicio
B1: CONTROL DE BOLETOS — TDS · PIN · PKS
B2: Un solo libro para los tres buses, dividido por meses. Se cargaron los viajes de octubre de TDS y PIN; PKS empieza vacío.
B4: MENÚ — haz clic en una opción para ir a esa hoja
B5: ✎ REGISTRO — anotar un viaje nuevo o corregir uno
B6: 🔎 CONSULTA — ver los viajes de un bus en un mes
B7: 📅 RESUMEN — totales de cada mes del año
B8: 📊 RESUMEN DIARIO — cada día del mes de un bus
B9: 🧾 FACTURAS — registrar facturas y calcular el IVA del mes
B10: Las celdas amarillas son las que tú escribes o eliges; todo lo demás se calcula solo.
B12: 1. REGISTRAR UN VIAJE (ventana emergente)
B13: Primera vez (una sola vez): clic derecho en la barra de acceso rápido (arriba a la izquierda) → Personalizar barra de herramientas de acceso rápido → en «Comandos disponibles en» elige «Comandos que no están en la cinta de opciones» → busca «Formulario…» → Agregar → Aceptar. En Excel para Mac: pestaña Datos → Formulario.
B14: Cada vez: ve a la hoja Registro, haz clic en cualquier celda con datos y pulsa el botón Formulario. Se abre una ventana con un campo por cada columna.
... B30: Cálculo: hoja automática; no escribas ahí. Capacidad: 1000 viajes, unos 12 meses para los tres buses (filas 2 a 1001 de Registro).

Sheet Registro
A1: Bus | B1: Fecha | C1: Destino | D1: Hora salida - llegada | E1: Boletos de ida (detalle) | F1: Descuento ida (monto) | G1: Boletos de llegada (detalle) | H1: Monto registrado que trajeron | I1: Gastos (concepto y monto) | J1: Otros gastos (concepto y monto) | K1: Observaciones | M1: ⌂ Inicio
A2: TDS | B2: 46296 | C2: Lp | D2: 08:30 - 15:30 | E2: 25x40; 3x50 | G2: 1x3300 | H2: 3300 | I2: Peaje 50; Veatico 50
A3: TDS | B3: 46297 | C3: Cbba | D3: 6:30 - 17:30 | E3: 15x40; 15x50; 5x60 | G3: 1x4060 | H3: 4060 | I3: Peaje 50; Veatico 50; Gasto 100
A4: TDS | B4: 46298 | C4: Cbba | D4: 5:30 - 15:30 | E4: 43x50; 2x80; 10x70 | G4: 1x3599 | H4: 3599 | I4: Peaje 50; Veatico 50 | J4: Diesel 8400
A5: TDS | B5: 46299 | C5: Lp | D5: 4:00 | E5: 43x40; 4x50; 7x60 | G5: 1x2080 | H5: 2080 | I5: Peaje 50; Veatico 50; Engrase 40
A6: TDS | B6: 46300 | C6: Cbba | D6: 9:30-17:00 | E6: 37x40; 2x50; 2x70; 8x60 | G6: 1x3300 | H6: 3300 | I6: Peaje 50; Diesel 400; Veatico 50 | J6: Diesel 7500
A7: TDS | B7: 46301 | C7: Lp | D7: 15:30-4:00 | E7: 9x60; 2x70; 45x50 | G7: 1x2350 | H7: 2350 | I7: Peaje 50; Veatico 50
A8: TDS | B8: 46302 | C8: Lp | D8: 6:30-14:30 | E8: 24x40; 4x60; 5x50 | G8: 1x2455 | H8: 2455 | I8: Peaje 50; Veatico 50
A9: TDS | B9: 46303 | C9: Lp | D9: 19:30-8:00 | E9: 35x40; 11x60 | G9: 1x2365 | H9: 2365 | I9: Peaje 50
A10: TDS | B10: 46304 | C10: Lp | D10: 4:00-11:00 | E10: 14x40; 31x50; 1x60; 4x70; 7x60 | G10: 1x2395 | H10: 2395
A11: TDS | B11: 46305 | C11: Cbba | D11: 7:00-14:30 | E11: 30x40; 12x35; 1x70 | G11: 1x3670 | H11: 3670 | I11: Peaje 50; Veatico 50 | J11: Diesel 8380
A12: TDS | B12: 46305 | C12: Lp | D12: 17:30-4:30 | E12: 19x40; 10x60; 5x50; 11x35 | G12: 1x2100 | H12: 2100
A13: TDS | B13: 46306 | C13: Cbba | D13: 12:00-19:00 | E13: 46x50; 4x70 | G13: 1x5280 | H13: 5280 | I13: Peaje 50; Veatico 50; Engrase 30
A14: TDS | B14: 46307 | C14: Lp | D14: 4:30-16:30 | E14: 38x40; 5x60; 8x50 | G14: 1x2855 | H14: 2855 | I14: Peaje 50; Veatico 50; Ayudante 120 | J14: Diesel 8190
A15: TDS | B15: 46308 | C15: Cbba | D15: 4:30-19:00 | E15: 36x40; 3x60; 2x50 | G15: 1x2960 | H15: 2960 | I15: Peaje 50; Veatico 50; Engrase 20
A16: TDS | B16: 46309 | C16: Lp | D16: 3:30-16:00 | E16: 29x40; 3x50; 10x60 | G16: 1x2070 | H16: 2070 | I16: Peaje 50; Veatico 50; Diesel 500
A17: TDS | B17: 46310 | C17: Lp | D17: 3:30-14:30 | E17: Sin boleto | G17: Sin boleto | H17: 2870 | I17: Peaje 50; Veatico 50; Extra 20 | J17: Diesel 8370
A18: TDS | B18: 46311 | C18: Lp | D18: 5:00-19:00 | E18: Sin boleto | G18: 1x3250 | H18: 3250 | I18: Peaje 50; Veatico 50; Engrase 40
A19: TDS | B19: 46312 | C19: Cbba | D19: 05:00-12:00 | E19: 29x50; 18x60; 11x80 | G19: 1x3360 | H19: 3360 | I19: Peaje 60; Veatico 50; Taxi 20 | J19: Diesel 5550
A20: TDS | B20: 46313 | C20: Lp | D20: 7:00-15:30 | E20: 37x40; 5x60 | G20: 1x3275 | H20: 3275 | I20: Peaje 45; Veatico 50
A21: TDS | B21: 46314 | C21: Cbba | D21: 3:30-12:00 | E21: 41x50; 7x40; 4x80 | G21: 1x3275 | H21: 3275 | I21: Peaje 45; Veatico 50; Ayudante 120
A22: TDS | B22: 46315 | C22: Lp | D22: 3:30-10:00 | E22: 42x50; 5x70; 2x60 | G22: 1x2340 | H22: 2340 | I22: Peaje 50; Veatico 50 | J22: Diesel 8500
A23: TDS | B23: 46316 | C23: Lp | D23: 4:30-17:00 | E23: 7x70; 35x50 | G23: Sin boleto | H23: 0
A24: TDS | B24: 46317 | C24: Cbba | D24: 6:30-15:30 | E24: 19x50; 6x40; 4x70; 4x60 | G24: Sin boleto | H24: 3760 | I24: Peaje 50; Veatico 50; Engrase 30
A25: TDS | B25: 46318 | C25: Lp | D25: 4:30-11:00 | E25: 47x50; 12x70 | G25: 1x2335 | H25: 2335 | I25: Peaje 45; Veatico 50 | J25: Diesel 8400
A26: PIN | B26: 46296 | C26: Lp | D26: 17:30-5:30 | E26: 31x40; 5x50; 7X60 | G26: 1X1925 | H26: 1925 | I26: Peaje 50; Veatico 50
A27: PIN | B27: 46297 | C27: Lp | D27: 17:30-5:30 | E27: 29x40; 13x50; 6x60; 4x70 | G27: 1x2520 | H27: 2520 | K27: Bultos 180
A28: PIN | B28: 46298 | C28: Lp | D28: 16:00-5:30 | E28: 32x40; 8x70; 4x60 | G28: 1x2215 | H28: 2215 | K28: Bultos 300
A29: PIN | B29: 46299 | C29: Cbba | D29: 15:30-5:00 | E29: 18x40; 15x50; 4x70; 8x60 | G29: 1x3860 | H29: 3860 | I29: Peaje 50; Veatico 50
A30: PIN | B30: 46300 | C30: Lp | D30: 13:30-20:30 | E30: 38x40; 10x60; 1x70 | G30: 1x2685 | H30: 2685 | I30: Peaje 50; Veatico 50; Engrase-Llantas 100; Gastos 65
A31: PIN | B31: 46302 | C31: Lp | D31: 04:30-12:00 | E31: 3x70; 5x60; 42x50 | G31: 1x2235 | H31: 2235 | I31: Peaje 52; Veatico 50; Gastos 70
A32: PIN | B32: 46303 | C32: Cbba | D32: 3:30-12:00 | E32: 1x80; 4x70; 7x60; 20x50 | G32: 1x3300 | H32: 3300 | I32: Peaje 50; Veatico 50; Gasto 80
A33: PIN | B33: 46304 | C33: Lp | D33: 4:30-13:30 | E33: 29x40; 18x50; 3x70; 8x60 | G33: 1x2855 | H33: 2855 | I33: Peaje 50; Veatico 50; engrase 45
A34: PIN | B34: 46305 | C34: Lp | D34: 5:30-14:30 | E34: 37x40; 10x60 | G34: 1x3015 | H34: 3015 | I34: Peaje 55; Veatico 50
A35: PIN | B35: 46306 | C35: Lp | D35: 4:30-13:00 | E35: 47x50; 2x70 | G35: 1x2825 | H35: 2825 | I35: Peaje 55; Veatico 50
A36: PIN | B36: 46306 | C36: Lp | D36: 16:00-7:30 | E36: 7x70; 14x40; 22x50; 5x60 | G36: 1x1425 | H36: 1425 | I36: Peaje 55; Veatico 50
A37: PIN | B37: 46307 | C37: Lp | D37: 18:00-12:30 | E37: 49x50; 12x70 | G37: 1x2795 | H37: 2795 | I37: Peaje 55; Veatico 50
A38: PIN | B38: 46308 | C38: Lp | D38: 3:30-10:00 | E38: 30x50; 2x70; 2x90; 1x60 | G38: 1x1415 | H38: 1415 | I38: Peaje 55; Veatico 50
A39: PIN | B39: 46309 | C39: Lp | D39: 19:30-8:30 | E39: 44x40; 11x60 | G39: 1x2115 | H39: 2115 | I39: Peaje 55; Veatico 50
A40: PIN | B40: 46310 | C40: Lp | D40: 19:30-7:30 | E40: 49x40; 1x50; 11x60 | G40: 1x1905 | H40: 1905 | I40: Peaje 55; Veatico 50
...

Sheet Consulta
A1: ="CONSULTA — "&$B$3&" · "&$F$3&" "&$D$3 -> CONSULTA — TDS · Octubre 2026
A2: Elige el bus, el año y el mes (celdas amarillas). Se muestran los viajes de ese bus y mes con todos los cálculos. «Fila en Registro» indica dónde corregir un dato.
A3: Bus: | B3: TDS | C3: Año: | D3: 2026 | E3: Mes: | F3: Octubre | G3: Clave: | H3: =$D$3*100+MATCH($F$3,{"Enero","Febrero","Marzo","Abril","Mayo","Junio","Julio","Agosto","Septiembre","Octubre","Noviembre","Diciembre"},0) -> 202610 | I3: ⌂ Inicio | J3: MONTO IDA (normal) | L3: DESCUENTO | N3: IDA NETO | P3: MONTO LLEGADA | R3: GASTOS + OTROS | T3: NETO FINAL
J4: =G7 -> 53675 | L4: =H7 -> 0 | N4: =I7 -> 53675 | P4: =N7 -> 72319 | R4: =P7+S7 -> 69567 | T4: =T7 -> 2752
A5: INFORMACIÓN DEL VIAJE | E5: IDA | J5: LLEGADA | O5: GASTOS Y NETO | R5: OTROS GASTOS | U5: NOTAS
A6: Fila en Registro | B6: Fecha | C6: Destino | D6: Hora salida - llegada | E6: Boletos de ida (detalle) | F6: Total boletos ida (cant.) | G6: Monto total de ida | H6: Descuento ida | I6: Monto ida neto | J6: Boletos de llegada (detalle) | K6: Total boletos llegada (cant.) | L6: Monto calculado | M6: Verificación | N6: Monto registrado que trajeron | O6: Gastos (detalle) | P6: Total gastos | Q6: Total menos gastos | R6: Otros gastos (detalle) | S6: Total otros gastos | T6: Neto final | U6: Observaciones
B7: TOTALES | C7: =COUNT(B8:B69) -> 26 | F7: =SUM(F8:F69) -> 1106 | G7: =SUM(G8:G69) -> 53675 | H7: =SUM(H8:H69) -> 0 | I7: =SUM(I8:I69) -> 53675 | K7: =SUM(K8:K69) -> 23 | L7: =SUM(L8:L69) -> 72319 | N7: =SUM(N8:N69) -> 72319 | P7: =SUM(P8:P69) -> 3577 | Q7: =SUM(Q8:Q69) -> 68742 | S7: =SUM(S8:S69) -> 65990 | T7: =SUM(T8:T69) -> 2752
A8: =IFERROR(MOD(SMALL(Cálculo!$O$2:$O$1001,ROWS(A$8:A8)),10000),"") -> 2 | B8: =IF($A8="","",IF(INDEX(Registro!$B$1:$B$1001,$A8)="","",INDEX(Registro!$B$1:$B$1001,$A8))) -> 46296 | C8: =IF($A8="","",IF(INDEX(Registro!$C$1:$C$1001,$A8)="","",INDEX(Registro!$C$1:$C$1001,$A8))) -> Lp | D8: =IF($A8="","",IF(INDEX(Registro!$D$1:$D$1001,$A8)="","",INDEX(Registro!$D$1:$D$1001,$A8))) -> 08:30 - 15:30 | E8: =IF($A8="","",IF(INDEX(Registro!$E$1:$E$1001,$A8)="","",INDEX(Registro!$E$1:$E$1001,$A8))) -> 25x40; 3x50 | F8: =IF($A8="","",IF(INDEX(Cálculo!$D$1:$D$1001,$A8)="","",INDEX(Cálculo!$D$1:$D$1001,$A8))) -> 28 | G8: =IF($A8="","",IF(INDEX(Cálculo!$E$1:$E$1001,$A8)="","",INDEX(Cálculo!$E$1:$E$1001,$A8))) -> 1150 | H8: =IF($A8="","",IF(INDEX(Cálculo!$F$1:$F$1001,$A8)="","",INDEX(Cálculo!$F$1:$F$1001,$A8))) | I8: =IF($A8="","",IF(INDEX(Cálculo!$G$1:$G$1001,$A8)="","",INDEX(Cálculo!$G$1:$G$1001,$A8))) -> 1150 | J8: =IF($A8="","",IF(INDEX(Registro!$G$1:$G$1001,$A8)="","",INDEX(Registro!$G$1:$G$1001,$A8))) -> 1x3300 | K8: =IF($A8="","",IF(INDEX(Cálculo!$H$1:$H$1001,$A8)="","",INDEX(Cálculo!$H$1:$H$1001,$A8))) -> 1 | L8: =IF($A8="","",IF(INDEX(Cálculo!$I$1:$I$1001,$A8)="","",INDEX(Cálculo!$I$1:$I$1001,$A8))) -> 3300 | M8: =IF($A8="","",IF(INDEX(Cálculo!$J$1:$J$1001,$A8)="","",INDEX(Cálculo!$J$1:$J$1001,$A8))) -> CONFORME | N8: =IF($A8="","",IF(INDEX(Registro!$H$1:$H$1001,$A8)="","",INDEX(Registro!$H$1:$H$1001,$A8))) -> 3300 | O8: =IF($A8="","",IF(INDEX(Registro!$I$1:$I$1001,$A8)="","",INDEX(Registro!$I$1:$I$1001,$A8))) -> Peaje 50; Veatico 50 | P8: =IF($A8="","",IF(INDEX(Cálculo!$K$1:$K$1001,$A8)="","",INDEX(Cálculo!$K$1:$K$1001,$A8))) -> 100 | Q8: =IF($A8="","",IF(INDEX(Cálculo!$M$1:$M$1001,$A8)="","",INDEX(Cálculo!$M$1:$M$1001,$A8))) -> 3200 | R8: =IF($A8="","",IF(INDEX(Registro!$J$1:$J$1001,$A8)="","",INDEX(Registro!$J$1:$J$1001,$A8))) | S8: =IF($A8="","",IF(INDEX(Cálculo!$L$1:$L$1001,$A8)="","",INDEX(Cálculo!$L$1:$L$1001,$A8))) | T8: =IF($A8="","",IF(INDEX(Cálculo!$N$1:$N$1001,$A8)="","",INDEX(Cálculo!$N$1:$N$1001,$A8))) -> 3200 | U8: =IF($A8="","",IF(INDEX(Registro!$K$1:$K$1001,$A8)="","",INDEX(Registro!$K$1:$K$1001,$A8)))
A9: =IFERROR(MOD(SMALL(Cálculo!$O$2:$O$1001,ROWS(A$8:A9)),10000),"") -> 3 | B9: =IF($A9="","",IF(INDEX(Registro!$B$1:$B$1001,$A9)="","",INDEX(Registro!$B$1:$B$1001,$A9))) -> 46297 | C9: =IF($A9="","",IF(INDEX(Registro!$C$1:$C$1001,$A9)="","",INDEX(Registro!$C$1:$C$1001,$A9))) -> Cbba | D9: =IF($A9="","",IF(INDEX(Registro!$D$1:$D$1001,$A9)="","",INDEX(Registro!$D$1:$D$1001,$A9))) -> 6:30 - 17:30 | E9: =IF($A9="","",IF(INDEX(Registro!$E$1:$E$1001,$A9)="","",INDEX(Registro!$E$1:$E$1001,$A9))) -> 15x40; 15x50; 5x60 | F9: =IF($A9="","",IF(INDEX(Cálculo!$D$1:$D$1001,$A9)="","",INDEX(Cálculo!$D$1:$D$1001,$A9))) -> 35 | G9: =IF($A9="","",IF(INDEX(Cálculo!$E$1:$E$1001,$A9)="","",INDEX(Cálculo!$E$1:$E$1001,$A9))) -> 1650 | H9: =IF($A9="","",IF(INDEX(Cálculo!$F$1:$F$1001,$A9)="","",INDEX(Cálculo!$F$1:$F$1001,$A9))) | I9: =IF($A9="","",IF(INDEX(Cálculo!$G$1:$G$1001,$A9)="","",INDEX(Cálculo!$G$1:$G$1001,$A9))) -> 1650 | J9: =IF($A9="","",IF(INDEX(Registro!$G$1:$G$1001,$A9)="","",INDEX(Registro!$G$1:$G$1001,$A9))) -> 1x4060 | K9: =IF($A9="","",IF(INDEX(Cálculo!$H$1:$H$1001,$A9)="","",INDEX(Cálculo!$H$1:$H$1001,$A9))) -> 1 | L9: =IF($A9="","",IF(INDEX(Cálculo!$I$1:$I$1001,$A9)="","",INDEX(Cálculo!$I$1:$I$1001,$A9))) -> 4060 | M9: =IF($A9="","",IF(INDEX(Cálculo!$J$1:$J$1001,$A9)="","",INDEX(Cálculo!$J$1:$J$1001,$A9))) -> CONFORME | N9: =IF($A9="","",IF(INDEX(Registro!$H$1:$H$1001,$A9)="","",INDEX(Registro!$H$1:$H$1001,$A9))) -> 4060 | O9: =IF($A9="","",IF(INDEX(Registro!$I$1:$I$1001,$A9)="","",INDEX(Registro!$I$1:$I$1001,$A9))) -> Peaje 50; Veatico 50; Gasto 100 | P9: =IF($A9="","",IF(INDEX(Cálculo!$K$1:$K$1001,$A9)="","",INDEX(Cálculo!$K$1:$K$1001,$A9))) -> 200 | Q9: =IF($A9="","",IF(INDEX(Cálculo!$M$1:$M$1001,$A9)="","",INDEX(Cálculo!$M$1:$M$1001,$A9))) -> 3860 | R9: =IF($A9="","",IF(INDEX(Registro!$J$1:$J$1001,$A9)="","",INDEX(Registro!$J$1:$J$1001,$A9))) | S9: =IF($A9="","",IF(INDEX(Cálculo!$L$1:$L$1001,$A9)="","",INDEX(Cálculo!$L$1:$L$1001,$A9))) | T9: =IF($A9="","",IF(INDEX(Cálculo!$N$1:$N$1001,$A9)="","",INDEX(Cálculo!$N$1:$N$1001,$A9))) -> 3860 | U9: =IF($A9="","",IF(INDEX(Registro!$K$1:$K$1001,$A9)="","",INDEX(Registro!$K$1:$K$1001,$A9)))
A10: =IFERROR(MOD(SMALL(Cálculo!$O$2:$O$1001,ROWS(A$8:A10)),10000),"") -> 4 | B10: =IF($A10="","",IF(INDEX(Registro!$B$1:$B$1001,$A10)="","",INDEX(Registro!$B$1:$B$1001,$A10))) -> 46298 | C10: =IF($A10="","",IF(INDEX(Registro!$C$1:$C$1001,$A10)="","",INDEX(Registro!$C$1:$C$1001,$A10))) -> Cbba | D10: =IF($A10="","",IF(INDEX(Registro!$D$1:$D$1001,$A10)="","",INDEX(Registro!$D$1:$D$1001,$A10))) -> 5:30 - 15:30 | E10: =IF($A10="","",IF(INDEX(Registro!$E$1:$E$1001,$A10)="","",INDEX(Registro!$E$1:$E$1001,$A10))) -> 43x50; 2x80; 10x70 | F10: =IF($A10="","",IF(INDEX(Cálculo!$D$1:$D$1001,$A10)="","",INDEX(Cálculo!$D$1:$D$1001,$A10))) -> 55 | G10: =IF($A10="","",IF(INDEX(Cálculo!$E$1:$E$1001,$A10)="","",INDEX(Cálculo!$E$1:$E$1001,$A10))) -> 3010 | H10: =IF($A10="","",IF(INDEX(Cálculo!$F$1:$F$1001,$A10)="","",INDEX(Cálculo!$F$1:$F$1001,$A10))) | I10: =IF($A10="","",IF(INDEX(Cálculo!$G$1:$G$1001,$A10)="","",INDEX(Cálculo!$G$1:$G$1001,$A10))) -> 3010 | J10: =IF($A10="","",IF(INDEX(Registro!$G$1:$G$1001,$A10)="","",INDEX(Registro!$G$1:$G$1001,$A10))) -> 1x3599 | K10: =IF($A10="","",IF(INDEX(Cálculo!$H$1:$H$1001,$A10)="","",INDEX(Cálculo!$H$1:$H$1001,$A10))) -> 1 | L10: =IF($A10="","",IF(INDEX(Cálculo!$I$1:$I$1001,$A10)="","",INDEX(Cálculo!$I$1:$I$1001,$A10))) -> 3599 | M10: =IF($A10="","",IF(INDEX(Cálculo!$J$1:$J$1001,$A10)="","",INDEX(Cálculo!$J$1:$J$1001,$A10))) -> CONFORME | N10: =IF($A10="","",IF(INDEX(Registro!$H$1:$H$1001,$A10)="","",INDEX(Registro!$H$1:$H$1001,$A10))) -> 3599 | O10: =IF($A10="","",IF(INDEX(Registro!$I$1:$I$1001,$A10)="","",INDEX(Registro!$I$1:$I$1001,$A10))) -> Peaje 50; Veatico 50 | P10: =IF($A10="","",IF(INDEX(Cálculo!$K$1:$K$1001,$A10)="","",INDEX(Cálculo!$K$1:$K$1001,$A10))) -> 100 | Q10: =IF($A10="","",IF(INDEX(Cálculo!$M$1:$M$1001,$A10)="","",INDEX(Cálculo!$M$1:$M$1001,$A10))) -> 3499 | R10: =IF($A10="","",IF(INDEX(Registro!$J$1:$J$1001,$A10)="","",INDEX(Registro!$J$1:$J$1001,$A10))) -> Diesel 8400 | S10: =IF($A10="","",IF(INDEX(Cálculo!$L$1:$L$1001,$A10)="","",INDEX(Cálculo!$L$1:$L$1001,$A10))) -> 8400 | T10: =IF($A10="","",IF(INDEX(Cálculo!$N$1:$N$1001,$A10)="","",INDEX(Cálculo!$N$1:$N$1001,$A10))) -> -4901 | U10: =IF($A10="","",IF(INDEX(Registro!$K$1:$K$1001,$A10)="","",INDEX(Registro!$K$1:$K$1001,$A10)))
A11: =IFERROR(MOD(SMALL(Cálculo!$O$2:$O$1001,ROWS(A$8:A11)),10000),"") -> 5 | B11: =IF($A11="","",IF(INDEX(Registro!$B$1:$B$1001,$A11)="","",INDEX(Registro!$B$1:$B$1001,$A11))) -> 46299 | C11: =IF($A11="","",IF(INDEX(Registro!$C$1:$C$1001,$A11)="","",INDEX(Registro!$C$1:$C$1001,$A11))) -> Lp | D11: =IF($A11="","",IF(INDEX(Registro!$D$1:$D$1001,$A11)="","",INDEX(Registro!$D$1:$D$1001,$A11))) -> 4:00 | E11: =IF($A11="","",IF(INDEX(Registro!$E$1:$E$1001,$A11)="","",INDEX(Registro!$E$1:$E$1001,$A11))) -> 43x40; 4x50; 7x60 | F11: =IF($A11="","",IF(INDEX(Cálculo!$D$1:$D$1001,$A11)="","",INDEX(Cálculo!$D$1:$D$1001,$A11))) -> 54 | G11: =IF($A11="","",IF(INDEX(Cálculo!$E$1:$E$1001,$A11)="","",INDEX(Cálculo!$E$1:$E$1001,$A11))) -> 2340 | H11: =IF($A11="","",IF(INDEX(Cálculo!$F$1:$F$1001,$A11)="","",INDEX(Cálculo!$F$1:$F$1001,$A11))) | I11: =IF($A11="","",IF(INDEX(Cálculo!$G$1:$G$1001,$A11)="","",INDEX(Cálculo!$G$1:$G$1001,$A11))) -> 2340 | J11: =IF($A11="","",IF(INDEX(Registro!$G$1:$G$1001,$A11)="","",INDEX(Registro!$G$1:$G$1001,$A11))) -> 1x2080 | K11: =IF($A11="","",IF(INDEX(Cálculo!$H$1:$H$1001,$A11)="","",INDEX(Cálculo!$H$1:$H$1001,$A11))) -> 1 | L11: =IF($A11="","",IF(INDEX(Cálculo!$I$1:$I$1001,$A11)="","",INDEX(Cálculo!$I$1:$I$1001,$A11))) -> 2080 | M11: =IF($A11="","",IF(INDEX(Cálculo!$J$1:$J$1001,$A11)="","",INDEX(Cálculo!$J$1:$J$1001,$A11))) -> CONFORME | N11: =IF($A11="","",IF(INDEX(Registro!$H$1:$H$1001,$A11)="","",INDEX(Registro!$H$1:$H$1001,$A11))) -> 2080 | O11: =IF($A11="","",IF(INDEX(Registro!$I$1:$I$1001,$A11)="","",INDEX(Registro!$I$1:$I$1001,$A11))) -> Peaje 50; Veatico 50; Engrase 40 | P11: =IF($A11="","",IF(INDEX(Cálculo!$K$1:$K$1001,$A11)="","",INDEX(Cálculo!$K$1:$K$1001,$A11))) -> 140 | Q11: =IF($A11="","",IF(INDEX(Cálculo!$M$1:$M$1001,$A11)="","",INDEX(Cálculo!$M$1:$M$1001,$A11))) -> 1940 | R11: =IF($A11="","",IF(INDEX(Registro!$J$1:$J$1001,$A11)="","",INDEX(Registro!$J$1:$J$1001,$A11))) | S11: =IF($A11="","",IF(INDEX(Cálculo!$L$1:$L$1001,$A11)="","",INDEX(Cálculo!$L$1:$L$1001,$A11))) | T11: =IF($A11="","",IF(INDEX(Cálculo!$N$1:$N$1001,$A11)="","",INDEX(Cálculo!$N$1:$N$1001,$A11))) -> 1940 | U11: =IF($A11="","",IF(INDEX(Registro!$K$1:$K$1001,$A11)="","",INDEX(Registro!$K$1:$K$1001,$A11)))
A12: =IFERROR(MOD(SMALL(Cálculo!$O$2:$O$1001,ROWS(A$8:A12)),10000),"") -> 6 | B12: =IF($A12="","",IF(INDEX(Registro!$B$1:$B$1001,$A12)="","",INDEX(Registro!$B$1:$B$1001,$A12))) -> 46300 | C12: =IF($A12="","",IF(INDEX(Registro!$C$1:$C$1001,$A12)="","",INDEX(Registro!$C$1:$C$1001,$A12))) -> Cbba | D12: =IF($A12="","",IF(INDEX(Registro!$D$1:$D$1001,$A12)="","",INDEX(Registro!$D$1:$D$1001,$A12))) -> 9:30-17:00 | E12: =IF($A12="","",IF(INDEX(Registro!$E$1:$E$1001,$A12)="","",INDEX(Registro!$E$1:$E$1001,$A12))) -> 37x40; 2x50; 2x70; 8x60 | F12: =IF($A12="","",IF(INDEX(Cálculo!$D$1:$D$1001,$A12)="","",INDEX(Cálculo!$D$1:$D$1001,$A12))) -> 49 | G12: =IF($A12="","",IF(INDEX(Cálculo!$E$1:$E$1001,$A12)="","",INDEX(Cálculo!$E$1:$E$1001,$A12))) -> 2200 | H12: =IF($A12="","",IF(INDEX(Cálculo!$F$1:$F$1001,$A12)="","",INDEX(Cálculo!$F$1:$F$1001,$A12))) | I12: =IF($A12="","",IF(INDEX(Cálculo!$G$1:$G$1001,$A12)="","",INDEX(Cálculo!$G$1:$G$1001,$A12))) -> 2200 | J12: =IF($A12="","",IF(INDEX(Registro!$G$1:$G$1001,$A12)="","",INDEX(Registro!$G$1:$G$1001,$A12))) -> 1x3300 | K12: =IF($A12="","",IF(INDEX(Cálculo!$H$1:$H$1001,$A12)="","",INDEX(Cálculo!$H$1:$H$1001,$A12))) -> 1 | L12: =IF($A12="","",IF(INDEX(Cálculo!$I$1:$I$1001,$A12)="","",INDEX(Cálculo!$I$1:$I$1001,$A12))) -> 3300 | M12: =IF($A12="","",IF(INDEX(Cálculo!$J$1:$J$1001,$A12)="","",INDEX(Cálculo!$J$1:$J$1001,$A12))) -> CONFORME | N12: =IF($A12="","",IF(INDEX(Registro!$H$1:$H$1001,$A12)="","",INDEX(Registro!$H$1:$H$1001,$A12))) -> 3300 | O12: =IF($A12="","",IF(INDEX(Registro!$I$1:$I$1001,$A12)="","",INDEX(Registro!$I$1:$I$1001,$A12))) -> Peaje 50; Diesel 400; Veatico 50 | P12: =IF($A12="","",IF(INDEX(Cálculo!$K$1:$K$1001,$A12)="","",INDEX(Cálculo!$K$1:$K$1001,$A12))) -> 500 | Q12: =IF($A12="","",IF(INDEX(Cálculo!$M$1:$M$1001,$A12)="","",INDEX(Cálculo!$M$1:$M$1001,$A12))) -> 2800 | R12: =IF($A12="","",IF(INDEX(Registro!$J$1:$J$1001,$A12)="","",INDEX(Registro!$J$1:$J$1001,$A12))) -> Diesel 7500 | S12: =IF($A12="","",IF(INDEX(Cálculo!$L$1:$L$1001,$A12)="","",INDEX(Cálculo!$L$1:$L$1001,$A12))) -> 7500 | T12: =IF($A12="","",IF(INDEX(Cálculo!$N$1:$N$1001,$A12)="","",INDEX(Cálculo!$N$1:$N$1001,$A12))) -> -4700 | U12: =IF($A12="","",IF(INDEX(Registro!$K$1:$K$1001,$A12)="","",INDEX(Registro!$K$1:$K$1001,$A12)))
A13: =IFERROR(MOD(SMALL(Cálculo!$O$2:$O$1001,ROWS(A$8:A13)),10000),"") -> 7 | B13: =IF($A13="","",IF(INDEX(Registro!$B$1:$B$1001,$A13)="","",INDEX(Registro!$B$1:$B$1001,$A13))) -> 46301 | C13: =IF($A13="","",IF(INDEX(Registro!$C$1:$C$1001,$A13)="","",INDEX(Registro!$C$1:$C$1001,$A13))) -> Lp | D13: =IF($A13="","",IF(INDEX(Registro!$D$1:$D$1001,$A13)="","",INDEX(Registro!$D$1:$D$1001,$A13))) -> 15:30-4:00 | E13: =IF($A13="","",IF(INDEX(Registro!$E$1:$E$1001,$A13)="","",INDEX(Registro!$E$1:$E$1001,$A13))) -> 9x60; 2x70; 45x50 | F13: =IF($A13="","",IF(INDEX(Cálculo!$D$1:$D$1001,$A13)="","",INDEX(Cálculo!$D$1:$D$1001,$A13))) -> 56 | G13: =IF($A13="","",IF(INDEX(Cálculo!$E$1:$E$1001,$A13)="","",INDEX(Cálculo!$E$1:$E$1001,$A13))) -> 2930 | H13: =IF($A13="","",IF(INDEX(Cálculo!$F$1:$F$1001,$A13)="","",INDEX(Cálculo!$F$1:$F$1001,$A13))) | I13: =IF($A13="","",IF(INDEX(Cálculo!$G$1:$G$1001,$A13)="","",INDEX(Cálculo!$G$1:$G$1001,$A13))) -> 2930 | J13: =IF($A13="","",IF(INDEX(Registro!$G$1:$G$1001,$A13)="","",INDEX(Registro!$G$1:$G$1001,$A13))) -> 1x2350 | K13: =IF($A13="","",IF(INDEX(Cálculo!$H$1:$H$1001,$A13)="","",INDEX(Cálculo!$H$1:$H$1001,$A13))) -> 1 | L13: =IF($A13="","",IF(INDEX(Cálculo!$I$1:$I$1001,$A13)="","",INDEX(Cálculo!$I$1:$I$1001,$A13))) -> 2350 | M13: =IF($A13="","",IF(INDEX(Cálculo!$J$1:$J$1001,$A13)="","",INDEX(Cálculo!$J$1:$J$1001,$A13))) -> CONFORME | N13: =IF($A13="","",IF(INDEX(Registro!$H$1:$H$1001,$A13)="","",INDEX(Registro!$H$1:$H$1001,$A13))) -> 2350 | O13: =IF($A13="","",IF(INDEX(Registro!$I$1:$I$1001,$A13)="","",INDEX(Registro!$I$1:$I$1001,$A13))) -> Peaje 50; Veatico 50 | P13: =IF($A13="","",IF(INDEX(Cálculo!$K$1:$K$1001,$A13)="","",INDEX(Cálculo!$K$1:$K$1001,$A13))) -> 100 | Q13: =IF($A13="","",IF(INDEX(Cálculo!$M$1:$M$1001,$A13)="","",INDEX(Cálculo!$M$1:$M$1001,$A13))) -> 2250 | R13: =IF($A13="","",IF(INDEX(Registro!$J$1:$J$1001,$A13)="","",INDEX(Registro!$J$1:$J$1001,$A13))) | S13: =IF($A13="","",IF(INDEX(Cálculo!$L$1:$L$1001,$A13)="","",INDEX(Cálculo!$L$1:$L$1001,$A13))) | T13: =IF($A13="","",IF(INDEX(Cálculo!$N$1:$N$1001,$A13)="","",INDEX(Cálculo!$N$1:$N$1001,$A13))) -> 2250 | U13: =IF($A13="","",IF(INDEX(Registro!$K$1:$K$1001,$A13)="","",INDEX(Registro!$K$1:$K$1001,$A13)))
A14: =IFERROR(MOD(SMALL(Cálculo!$O$2:$O$1001,ROWS(A$8:A14)),10000),"") -> 8 | B14: =IF($A14="","",IF(INDEX(Registro!$B$1:$B$1001,$A14)="","",INDEX(Registro!$B$1:$B$1001,$A14))) -> 46302 | C14: =IF($A14="","",IF(INDEX(Registro!$C$1:$C$1001,$A14)="","",INDEX(Registro!$C$1:$C$1001,$A14))) -> Lp | D14: =IF($A14="","",IF(INDEX(Registro!$D$1:$D$1001,$A14)="","",INDEX(Registro!$D$1:$D$1001,$A14))) -> 6:30-14:30 | E14: =IF($A14="","",IF(INDEX(Registro!$E$1:$E$1001,$A14)="","",INDEX(Registro!$E$1:$E$1001,$A14))) -> 24x40; 4x60; 5x50 | F14: =IF($A14="","",IF(INDEX(Cálculo!$D$1:$D$1001,$A14)="","",INDEX(Cálculo!$D$1:$D$1001,$A14))) -> 33 | G14: =IF($A14="","",IF(INDEX(Cálculo!$E$1:$E$1001,$A14)="","",INDEX(Cálculo!$E$1:$E$1001,$A14))) -> 1450 | H14: =IF($A14="","",IF(INDEX(Cálculo!$F$1:$F$1001,$A14)="","",INDEX(Cálculo!$F$1:$F$1001,$A14))) | I14: =IF($A14="","",IF(INDEX(Cálculo!$G$1:$G$1001,$A14)="","",INDEX(Cálculo!$G$1:$G$1001,$A14))) -> 1450 | J14: =IF($A14="","",IF(INDEX(Registro!$G$1:$G$1001,$A14)="","",INDEX(Registro!$G$1:$G$1001,$A14))) -> 1x2455 | K14: =IF($A14="","",IF(INDEX(Cálculo!$H$1:$H$1001,$A14)="","",INDEX(Cálculo!$H$1:$H$1001,$A14))) -> 1 | L14: =IF($A14="","",IF(INDEX(Cálculo!$I$1:$I$1001,$A14)="","",INDEX(Cálculo!$I$1:$I$1001,$A14))) -> 2455 | M14: =IF($A14="","",IF(INDEX(Cálculo!$J$1:$J$1001,$A14)="","",INDEX(Cálculo!$J$1:$J$1001,$A14))) -> CONFORME | N14: =IF($A14="","",IF(INDEX(Registro!$H$1:$H$1001,$A14)="","",INDEX(Registro!$H$1:$H$1001,$A14))) -> 2455 | O14: =IF($A14="","",IF(INDEX(Registro!$I$1:$I$1001,$A14)="","",INDEX(Registro!$I$1:$I$1001,$A14))) -> Peaje 50; Veatico 50 | P14: =IF($A14="","",IF(INDEX(Cálculo!$K$1:$K$1001,$A14)="","",INDEX(Cálculo!$K$1:$K$1001,$A14))) -> 100 | Q14: =IF($A14="","",IF(INDEX(Cálculo!$M$1:$M$1001,$A14)="","",INDEX(Cálculo!$M$1:$M$1001,$A14))) -> 2355 | R14: =IF($A14="","",IF(INDEX(Registro!$J$1:$J$1001,$A14)="","",INDEX(Registro!$J$1:$J$1001,$A14))) | S14: =IF($A14="","",IF(INDEX(Cálculo!$L$1:$L$1001,$A14)="","",INDEX(Cálculo!$L$1:$L$1001,$A14))) | T14: =IF($A14="","",IF(INDEX(Cálculo!$N$1:$N$1001,$A14)="","",INDEX(Cálculo!$N$1:$N$1001,$A14))) -> 2355 | U14: =IF($A14="","",IF(INDEX(Registro!$K$1:$K$1001,$A14)="","",INDEX(Registro!$K$1:$K$1001,$A14)))
A15: =IFERROR(MOD(SMALL(Cálculo!$O$2:$O$1001,ROWS(A$8:A15)),10000),"") -> 9 | B15: =IF($A15="","",IF(INDEX(Registro!$B$1:$B$1001,$A15)="","",INDEX(Registro!$B$1:$B$1001,$A15))) -> 46303 | C15: =IF($A15="","",IF(INDEX(Registro!$C$1:$C$1001,$A15)="","",INDEX(Registro!$C$1:$C$1001,$A15))) -> Lp | D15: =IF($A15="","",IF(INDEX(Registro!$D$1:$D$1001,$A15)="","",INDEX(Registro!$D$1:$D$1001,$A15))) -> 19:30-8:00 | E15: =IF($A15="","",IF(INDEX(Registro!$E$1:$E$1001,$A15)="","",INDEX(Registro!$E$1:$E$1001,$A15))) -> 35x40; 11x60 | F15: =IF($A15="","",IF(INDEX(Cálculo!$D$1:$D$1001,$A15)="","",INDEX(Cálculo!$D$1:$D$1001,$A15))) -> 46 | G15: =IF($A15="","",IF(INDEX(Cálculo!$E$1:$E$1001,$A15)="","",INDEX(Cálculo!$E$1:$E$1001,$A15))) -> 2060 | H15: =IF($A15="","",IF(INDEX(Cálculo!$F$1:$F$1001,$A15)="","",INDEX(Cálculo!$F$1:$F$1001,$A15))) | I15: =IF($A15="","",IF(INDEX(Cálculo!$G$1:$G$1001,$A15)="","",INDEX(Cálculo!$G$1:$G$1001,$A15))) -> 2060 | J15: =IF($A15="","",IF(INDEX(Registro!$G$1:$G$1001,$A15)="","",INDEX(Registro!$G$1:$G$1001,$A15))) -> 1x2365 | K15: =IF($A15="","",IF(INDEX(Cálculo!$H$1:$H$1001,$A15)="","",INDEX(Cálculo!$H$1:$H$1001,$A15))) -> 1 | L15: =IF($A15="","",IF(INDEX(Cálculo!$I$1:$I$1001,$A15)="","",INDEX(Cálculo!$I$1:$I$1001,$A15))) -> 2365 | M15: =IF($A15="","",IF(INDEX(Cálculo!$J$1:$J$1001,$A15)="","",INDEX(Cálculo!$J$1:$J$1001,$A15))) -> CONFORME | N15: =IF($A15="","",IF(INDEX(Registro!$H$1:$H$1001,$A15)="","",INDEX(Registro!$H$1:$H$1001,$A15))) -> 2365 | O15: =IF($A15="","",IF(INDEX(Registro!$I$1:$I$1001,$A15)="","",INDEX(Registro!$I$1:$I$1001,$A15))) -> Peaje 50 | P15: =IF($A15="","",IF(INDEX(Cálculo!$K$1:$K$1001,$A15)="","",INDEX(Cálculo!$K$1:$K$1001,$A15))) -> 50 | Q15: =IF($A15="","",IF(INDEX(Cálculo!$M$1:$M$1001,$A15)="","",INDEX(Cálculo!$M$1:$M$1001,$A15))) -> 2315 | R15: =IF($A15="","",IF(INDEX(Registro!$J$1:$J$1001,$A15)="","",INDEX(Registro!$J$1:$J$1001,$A15))) | S15: =IF($A15="","",IF(INDEX(Cálculo!$L$1:$L$1001,$A15)="","",INDEX(Cálculo!$L$1:$L$1001,$A15))) | T15: =IF($A15="","",IF(INDEX(Cálculo!$N$1:$N$1001,$A15)="","",INDEX(Cálculo!$N$1:$N$1001,$A15))) -> 2315 | U15: =IF($A15="","",IF(INDEX(Registro!$K$1:$K$1001,$A15)="","",INDEX(Registro!$K$1:$K$1001,$A15)))
A16: =IFERROR(MOD(SMALL(Cálculo!$O$2:$O$1001,ROWS(A$8:A16)),10000),"") -> 10 | B16: =IF($A16="","",IF(INDEX(Registro!$B$1:$B$1001,$A16)="","",INDEX(Registro!$B$1:$B$1001,$A16))) -> 46304 | C16: =IF($A16="","",IF(INDEX(Registro!$C$1:$C$1001,$A16)="","",INDEX(Registro!$C$1:$C$1001,$A16))) -> Lp | D16: =IF($A16="","",IF(INDEX(Registro!$D$1:$D$1001,$A16)="","",INDEX(Registro!$D$1:$D$1001,$A16))) -> 4:00-11:00 | E16: =IF($A16="","",IF(INDEX(Registro!$E$1:$E$1001,$A16)="","",INDEX(Registro!$E$1:$E$1001,$A16))) -> 14x40; 31x50; 1x60; 4x70; 7x60 | F16: =IF($A16="","",IF(INDEX(Cálculo!$D$1:$D$1001,$A16)="","",INDEX(Cálculo!$D$1:$D$1001,$A16))) -> 57 | G16: =IF($A16="","",IF(INDEX(Cálculo!$E$1:$E$1001,$A16)="","",INDEX(Cálculo!$E$1:$E$1001,$A16))) -> 2870 | H16: =IF($A16="","",IF(INDEX(Cálculo!$F$1:$F$1001,$A16)="","",INDEX(Cálculo!$F$1:$F$1001,$A16))) | I16: =IF($A16="","",IF(INDEX(Cálculo!$G$1:$G$1001,$A16)="","",INDEX(Cálculo!$G$1:$G$1001,$A16))) -> 2870 | J16: =IF($A16="","",IF(INDEX(Registro!$G$1:$G$1001,$A16)="","",INDEX(Registro!$G$1:$G$1001,$A16))) -> 1x2395 | K16: =IF($A16="","",IF(INDEX(Cálculo!$H$1:$H$1001,$A16)="","",INDEX(Cálculo!$H$1:$H$1001,$A16))) -> 1 | L16: =IF($A16="","",IF(INDEX(Cálculo!$I$1:$I$1001,$A16)="","",INDEX(Cálculo!$I$1:$I$1001,$A16))) -> 2395 | M16: =IF($A16="","",IF(INDEX(Cálculo!$J$1:$J$1001,$A16)="","",INDEX(Cálculo!$J$1:$J$1001,$A16))) -> CONFORME | N16: =IF($A16="","",IF(INDEX(Registro!$H$1:$H$1001,$A16)="","",INDEX(Registro!$H$1:$H$1001,$A16))) -> 2395 | O16: =IF($A16="","",IF(INDEX(Registro!$I$1:$I$1001,$A16)="","",INDEX(Registro!$I$1:$I$1001,$A16))) | P16: =IF($A16="","",IF(INDEX(Cálculo!$K$1:$K$1001,$A16)="","",INDEX(Cálculo!$K$1:$K$1001,$A16))) | Q16: =IF($A16="","",IF(INDEX(Cálculo!$M$1:$M$1001,$A16)="","",INDEX(Cálculo!$M$1:$M$1001,$A16))) -> 2395 | R16: =IF($A16="","",IF(INDEX(Registro!$J$1:$J$1001,$A16)="","",INDEX(Registro!$J$1:$J$1001,$A16))) | S16: =IF($A16="","",IF(INDEX(Cálculo!$L$1:$L$1001,$A16)="","",INDEX(Cálculo!$L$1:$L$1001,$A16))) | T16: =IF($A16="","",IF(INDEX(Cálculo!$N$1:$N$1001,$A16)="","",INDEX(Cálculo!$N$1:$N$1001,$A16))) -> 2395 | U16: =IF($A16="","",IF(INDEX(Registro!$K$1:$K$1001,$A16)="","",INDEX(Registro!$K$1:$K$1001,$A16)))
A17: =IFERROR(MOD(SMALL(Cálculo!$O$2:$O$1001,ROWS(A$8:A17)),10000),"") -> 11 | B17: =IF($A17="","",IF(INDEX(Registro!$B$1:$B$1001,$A17)="","",INDEX(Registro!$B$1:$B$1001,$A17))) -> 46305 | C17: =IF($A17="","",IF(INDEX(Registro!$C$1:$C$1001,$A17)="","",INDEX(Registro!$C$1:$C$1001,$A17))) -> Cbba | D17: =IF($A17="","",IF(INDEX(Registro!$D$1:$D$1001,$A17)="","",INDEX(Registro!$D$1:$D$1001,$A17))) -> 7:00-14:30 | E17: =IF($A17="","",IF(INDEX(Registro!$E$1:$E$1001,$A17)="","",INDEX(Registro!$E$1:$E$1001,$A17))) -> 30x40; 12x35; 1x70 | F17: =IF($A17="","",IF(INDEX(Cálculo!$D$1:$D$1001,$A17)="","",INDEX(Cálculo!$D$1:$D$1001,$A17))) -> 43 | G17: =IF($A17="","",IF(INDEX(Cálculo!$E$1:$E$1001,$A17)="","",INDEX(Cálculo!$E$1:$E$1001,$A17))) -> 1690 | H17: =IF($A17="","",IF(INDEX(Cálculo!$F$1:$F$1001,$A17)="","",INDEX(Cálculo!$F$1:$F$1001,$A17))) | I17: =IF($A17="","",IF(INDEX(Cálculo!$G$1:$G$1001,$A17)="","",INDEX(Cálculo!$G$1:$G$1001,$A17))) -> 1690 | J17: =IF($A17="","",IF(INDEX(Registro!$G$1:$G$1001,$A17)="","",INDEX(Registro!$G$1:$G$1001,$A17))) -> 1x3670 | K17: =IF($A17="","",IF(INDEX(Cálculo!$H$1:$H$1001,$A17)="","",INDEX(Cálculo!$H$1:$H$1001,$A17))) -> 1 | L17: =IF($A17="","",IF(INDEX(Cálculo!$I$1:$I$1001,$A17)="","",INDEX(Cálculo!$I$1:$I$1001,$A17))) -> 3670 | M17: =IF($A17="","",IF(INDEX(Cálculo!$J$1:$J$1001,$A17)="","",INDEX(Cálculo!$J$1:$J$1001,$A17))) -> CONFORME | N17: =IF($A17="","",IF(INDEX(Registro!$H$1:$H$1001,$A17)="","",INDEX(Registro!$H$1:$H$1001,$A17))) -> 3670 | O17: =IF($A17="","",IF(INDEX(Registro!$I$1:$I$1001,$A17)="","",INDEX(Registro!$I$1:$I$1001,$A17))) -> Peaje 50; Veatico 50 | P17: =IF($A17="","",IF(INDEX(Cálculo!$K$1:$K$1001,$A17)="","",INDEX(Cálculo!$K$1:$K$1001,$A17))) -> 100 | Q17: =IF($A17="","",IF(INDEX(Cálculo!$M$1:$M$1001,$A17)="","",INDEX(Cálculo!$M$1:$M$1001,$A17))) -> 3570 | R17: =IF($A17="","",IF(INDEX(Registro!$J$1:$J$1001,$A17)="","",INDEX(Registro!$J$1:$J$1001,$A17))) -> Diesel 8380 | S17: =IF($A17="","",IF(INDEX(Cálculo!$L$1:$L$1001,$A17)="","",INDEX(Cálculo!$L$1:$L$1001,$A17))) -> 8380 | T17: =IF($A17="","",IF(INDEX(Cálculo!$N$1:$N$1001,$A17)="","",INDEX(Cálculo!$N$1:$N$1001,$A17))) -> -4810 | U17: =IF($A17="","",IF(INDEX(Registro!$K$1:$K$1001,$A17)="","",INDEX(Registro!$K$1:$K$1001,$A17)))
A18: =IFERROR(MOD(SMALL(Cálculo!$O$2:$O$1001,ROWS(A$8:A18)),10000),"") -> 12 | B18: =IF($A18="","",IF(INDEX(Registro!$B$1:$B$1001,$A18)="","",INDEX(Registro!$B$1:$B$1001,$A18))) -> 46305 | C18: =IF($A18="","",IF(INDEX(Registro!$C$1:$C$1001,$A18)="","",INDEX(Registro!$C$1:$C$1001,$A18))) -> Lp | D18: =IF($A18="","",IF(INDEX(Registro!$D$1:$D$1001,$A18)="","",INDEX(Registro!$D$1:$D$1001,$A18))) -> 17:30-4:30 | E18: =IF($A18="","",IF(INDEX(Registro!$E$1:$E$1001,$A18)="","",INDEX(Registro!$E$1:$E$1001,$A18))) -> 19x40; 10x60; 5x50; 11x35 | F18: =IF($A18="","",IF(INDEX(Cálculo!$D$1:$D$1001,$A18)="","",INDEX(Cálculo!$D$1:$D$1001,$A18))) -> 45 | G18: =IF($A18="","",IF(INDEX(Cálculo!$E$1:$E$1001,$A18)="","",INDEX(Cálculo!$E$1:$E$1001,$A18))) -> 1995 | H18: =IF($A18="","",IF(INDEX(Cálculo!$F$1:$F$1001,$A18)="","",INDEX(Cálculo!$F$1:$F$1001,$A18))) | I18: =IF($A18="","",IF(INDEX(Cálculo!$G$1:$G$1001,$A18)="","",INDEX(Cálculo!$G$1:$G$1001,$A18))) -> 1995 | J18: =IF($A18="","",IF(INDEX(Registro!$G$1:$G$1001,$A18)="","",INDEX(Registro!$G$1:$G$1001,$A18))) -> 1x2100 | K18: =IF($A18="","",IF(INDEX(Cálculo!$H$1:$H$1001,$A18)="","",INDEX(Cálculo!$H$1:$H$1001,$A18))) -> 1 | L18: =IF($A18="","",IF(INDEX(Cálculo!$I$1:$I$1001,$A18)="","",INDEX(Cálculo!$I$1:$I$1001,$A18))) -> 2100 | M18: =IF($A18="","",IF(INDEX(Cálculo!$J$1:$J$1001,$A18)="","",INDEX(Cálculo!$J$1:$J$1001,$A18))) -> CONFORME | N18: =IF($A18="","",IF(INDEX(Registro!$H$1:$H$1001,$A18)="","",INDEX(Registro!$H$1:$H$1001,$A18))) -> 2100 | O18: =IF($A18="","",IF(INDEX(Registro!$I$1:$I$1001,$A18)="","",INDEX(Registro!$I$1:$I$1001,$A18))) | P18: =IF($A18="","",IF(INDEX(Cálculo!$K$1:$K$1001,$A18)="","",INDEX(Cálculo!$K$1:$K$1001,$A18))) | Q18: =IF($A18="","",IF(INDEX(Cálculo!$M$1:$M$1001,$A18)="","",INDEX(Cálculo!$M$1:$M$1001,$A18))) -> 2100 | R18: =IF($A18="","",IF(INDEX(Registro!$J$1:$J$1001,$A18)="","",INDEX(Registro!$J$1:$J$1001,$A18))) | S18: =IF($A18="","",IF(INDEX(Cálculo!$L$1:$L$1001,$A18)="","",INDEX(Cálculo!$L$1:$L$1001,$A18))) | T18: =IF($A18="","",IF(INDEX(Cálculo!$N$1:$N$1001,$A18)="","",INDEX(Cálculo!$N$1:$N$1001,$A18))) -> 2100 | U18: =IF($A18="","",IF(INDEX(Registro!$K$1:$K$1001,$A18)="","",INDEX(Registro!$K$1:$K$1001,$A18)))
A19: =IFERROR(MOD(SMALL(Cálculo!$O$2:$O$1001,ROWS(A$8:A19)),10000),"") -> 13 | B19: =IF($A19="","",IF(INDEX(Registro!$B$1:$B$1001,$A19)="","",INDEX(Registro!$B$1:$B$1001,$A19))) -> 46306 | C19: =IF($A19="","",IF(INDEX(Registro!$C$1:$C$1001,$A19)="","",INDEX(Registro!$C$1:$C$1001,$A19))) -> Cbba | D19: =IF($A19="","",IF(INDEX(Registro!$D$1:$D$1001,$A19)="","",INDEX(Registro!$D$1:$D$1001,$A19))) -> 12:00-19:00 | E19: =IF($A19="","",IF(INDEX(Registro!$E$1:$E$1001,$A19)="","",INDEX(Registro!$E$1:$E$1001,$A19))) -> 46x50; 4x70 | F19: =IF($A19="","",IF(INDEX(Cálculo!$D$1:$D$1001,$A19)="","",INDEX(Cálculo!$D$1:$D$1001,$A19))) -> 50 | G19: =IF($A19="","",IF(INDEX(Cálculo!$E$1:$E$1001,$A19)="","",INDEX(Cálculo!$E$1:$E$1001,$A19))) -> 2580 | H19: =IF($A19="","",IF(INDEX(Cálculo!$F$1:$F$1001,$A19)="","",INDEX(Cálculo!$F$1:$F$1001,$A19))) | I19: =IF($A19="","",IF(INDEX(Cálculo!$G$1:$G$1001,$A19)="","",INDEX(Cálculo!$G$1:$G$1001,$A19))) -> 2580 | J19: =IF($A19="","",IF(INDEX(Registro!$G$1:$G$1001,$A19)="","",INDEX(Registro!$G$1:$G$1001,$A19))) -> 1x5280 | K19: =IF($A19="","",IF(INDEX(Cálculo!$H$1:$H$1001,$A19)="","",INDEX(Cálculo!$H$1:$H$1001,$A19))) -> 1 | L19: =IF($A19="","",IF(INDEX(Cálculo!$I$1:$I$1001,$A19)="","",INDEX(Cálculo!$I$1:$I$1001,$A19))) -> 5280 | M19: =IF($A19="","",IF(INDEX(Cálculo!$J$1:$J$1001,$A19)="","",INDEX(Cálculo!$J$1:$J$1001,$A19))) -> CONFORME | N19: =IF($A19="","",IF(INDEX(Registro!$H$1:$H$1001,$A19)="","",INDEX(Registro!$H$1:$H$1001,$A19))) -> 5280 | O19: =IF($A19="","",IF(INDEX(Registro!$I$1:$I$1001,$A19)="","",INDEX(Registro!$I$1:$I$1001,$A19))) -> Peaje 50; Veatico 50; Engrase 30 | P19: =IF($A19="","",IF(INDEX(Cálculo!$K$1:$K$1001,$A19)="","",INDEX(Cálculo!$K$1:$K$1001,$A19))) -> 130 | Q19: =IF($A19="","",IF(INDEX(Cálculo!$M$1:$M$1001,$A19)="","",INDEX(Cálculo!$M$1:$M$1001,$A19))) -> 5150 | R19: =IF($A19="","",IF(INDEX(Registro!$J$1:$J$1001,$A19)="","",INDEX(Registro!$J$1:$J$1001,$A19))) | S19: =IF($A19="","",IF(INDEX(Cálculo!$L$1:$L$1001,$A19)="","",INDEX(Cálculo!$L$1:$L$1001,$A19))) | T19: =IF($A19="","",IF(INDEX(Cálculo!$N$1:$N$1001,$A19)="","",INDEX(Cálculo!$N$1:$N$1001,$A19))) -> 5150 | U19: =IF($A19="","",IF(INDEX(Registro!$K$1:$K$1001,$A19)="","",INDEX(Registro!$K$1:$K$1001,$A19)))
... A69: =IFERROR(MOD(SMALL(Cálculo!$O$2:$O$1001,ROWS(A$8:A69)),10000),"") | B69: =IF($A69="","",IF(INDEX(Registro!$B$1:$B$1001,$A69)="","",INDEX(Registro!$B$1:$B$1001,$A69))) | C69: =IF($A69="","",IF(INDEX(Registro!$C$1:$C$1001,$A69)="","",INDEX(Registro!$C$1:$C$1001,$A69))) | D69: =IF($A69="","",IF(INDEX(Registro!$D$1:$D$1001,$A69)="","",INDEX(Registro!$D$1:$D$1001,$A69))) | E69: =IF($A69="","",IF(INDEX(Registro!$E$1:$E$1001,$A69)="","",INDEX(Registro!$E$1:$E$1001,$A69))) | F69: =IF($A69="","",IF(INDEX(Cálculo!$D$1:$D$1001,$A69)="","",INDEX(Cálculo!$D$1:$D$1001,$A69))) | G69: =IF($A69="","",IF(INDEX(Cálculo!$E$1:$E$1001,$A69)="","",INDEX(Cálculo!$E$1:$E$1001,$A69))) | H69: =IF($A69="","",IF(INDEX(Cálculo!$F$1:$F$1001,$A69)="","",INDEX(Cálculo!$F$1:$F$1001,$A69))) | I69: =IF($A69="","",IF(INDEX(Cálculo!$G$1:$G$1001,$A69)="","",INDEX(Cálculo!$G$1:$G$1001,$A69))) | J69: =IF($A69="","",IF(INDEX(Registro!$G$1:$G$1001,$A69)="","",INDEX(Registro!$G$1:$G$1001,$A69))) | K69: =IF($A69="","",IF(INDEX(Cálculo!$H$1:$H$1001,$A69)="","",INDEX(Cálculo!$H$1:$H$1001,$A69))) | L69: =IF($A69="","",IF(INDEX(Cálculo!$I$1:$I$1001,$A69)="","",INDEX(Cálculo!$I$1:$I$1001,$A69))) | M69: =IF($A69="","",IF(INDEX(Cálculo!$J$1:$J$1001,$A69)="","",INDEX(Cálculo!$J$1:$J$1001,$A69))) | N69: =IF($A69="","",IF(INDEX(Registro!$H$1:$H$1001,$A69)="","",INDEX(Registro!$H$1:$H$1001,$A69))) | O69: =IF($A69="","",IF(INDEX(Registro!$I$1:$I$1001,$A69)="","",INDEX(Registro!$I$1:$I$1001,$A69))) | P69: =IF($A69="","",IF(INDEX(Cálculo!$K$1:$K$1001,$A69)="","",INDEX(Cálculo!$K$1:$K$1001,$A69))) | Q69: =IF($A69="","",IF(INDEX(Cálculo!$M$1:$M$1001,$A69)="","",INDEX(Cálculo!$M$1:$M$1001,$A69))) | R69: =IF($A69="","",IF(INDEX(Registro!$J$1:$J$1001,$A69)="","",INDEX(Registro!$J$1:$J$1001,$A69))) | S69: =IF($A69="","",IF(INDEX(Cálculo!$L$1:$L$1001,$A69)="","",INDEX(Cálculo!$L$1:$L$1001,$A69))) | T69: =IF($A69="","",IF(INDEX(Cálculo!$N$1:$N$1001,$A69)="","",INDEX(Cálculo!$N$1:$N$1001,$A69))) | U69: =IF($A69="","",IF(INDEX(Registro!$K$1:$K$1001,$A69)="","",INDEX(Registro!$K$1:$K$1001,$A69)))

Sheet Resumen
A1: ="RESUMEN DEL AÑO "&$B$3&" — POR MES Y BUS" -> RESUMEN DEL AÑO 2026 — POR MES Y BUS
A2: Cambia el año en la celda amarilla. Todo se calcula solo a partir de la hoja Registro. Monto ida = total de los boletos de ida. Descuento = descuentos registrados (solo afectan a la ida). Ida neto = Monto ida − Descuento. Monto llegada = monto registrado que trajeron. Neto final = monto llegada − gastos − otros gastos. Ida y llegada van separados.
A3: Año: | B3: 2026 | D3: ⌂ Inicio
C5: TDS | K5: PIN | S5: PKS | AA5: TODOS LOS BUSES
A6: N° | B6: Mes | C6: Viajes | D6: Boletos | E6: Monto ida | F6: Descuento | G6: Ida neto | H6: Monto llegada | I6: Gastos | J6: Neto final | K6: Viajes | L6: Boletos | M6: Monto ida | N6: Descuento | O6: Ida neto | P6: Monto llegada | Q6: Gastos | R6: Neto final | S6: Viajes | T6: Boletos | U6: Monto ida | V6: Descuento | W6: Ida neto | X6: Monto llegada | Y6: Gastos | Z6: Neto final | AA6: Viajes | AB6: Monto ida | AC6: Descuento | AD6: Ida neto | AE6: Monto llegada | AF6: Neto final
A7: 1 | B7: Enero | C7: =COUNTIFS(Cálculo!$A$2:$A$1001,C$5,Cálculo!$C$2:$C$1001,$B$3*100+$A7) -> 0 | D7: =SUMIFS(Cálculo!$D$2:$D$1001,Cálculo!$A$2:$A$1001,C$5,Cálculo!$C$2:$C$1001,$B$3*100+$A7)+SUMIFS(Cálculo!$H$2:$H$1001,Cálculo!$A$2:$A$1001,C$5,Cálculo!$C$2:$C$1001,$B$3*100+$A7) -> 0 | E7: =SUMIFS(Cálculo!$E$2:$E$1001,Cálculo!$A$2:$A$1001,C$5,Cálculo!$C$2:$C$1001,$B$3*100+$A7) -> 0 | F7: =SUMIFS(Cálculo!$F$2:$F$1001,Cálculo!$A$2:$A$1001,C$5,Cálculo!$C$2:$C$1001,$B$3*100+$A7) -> 0 | G7: =E7-F7 -> 0 | H7: =SUMIFS(Registro!$H$2:$H$1001,Cálculo!$A$2:$A$1001,C$5,Cálculo!$C$2:$C$1001,$B$3*100+$A7) -> 0 | I7: =SUMIFS(Cálculo!$K$2:$K$1001,Cálculo!$A$2:$A$1001,C$5,Cálculo!$C$2:$C$1001,$B$3*100+$A7)+SUMIFS(Cálculo!$L$2:$L$1001,Cálculo!$A$2:$A$1001,C$5,Cálculo!$C$2:$C$1001,$B$3*100+$A7) -> 0 | J7: =SUMIFS(Cálculo!$N$2:$N$1001,Cálculo!$A$2:$A$1001,C$5,Cálculo!$C$2:$C$1001,$B$3*100+$A7) -> 0 | K7: =COUNTIFS(Cálculo!$A$2:$A$1001,K$5,Cálculo!$C$2:$C$1001,$B$3*100+$A7) -> 0 | L7: =SUMIFS(Cálculo!$D$2:$D$1001,Cálculo!$A$2:$A$1001,K$5,Cálculo!$C$2:$C$1001,$B$3*100+$A7)+SUMIFS(Cálculo!$H$2:$H$1001,Cálculo!$A$2:$A$1001,K$5,Cálculo!$C$2:$C$1001,$B$3*100+$A7) -> 0 | M7: =SUMIFS(Cálculo!$E$2:$E$1001,Cálculo!$A$2:$A$1001,K$5,Cálculo!$C$2:$C$1001,$B$3*100+$A7) -> 0 | N7: =SUMIFS(Cálculo!$F$2:$F$1001,Cálculo!$A$2:$A$1001,K$5,Cálculo!$C$2:$C$1001,$B$3*100+$A7) -> 0 | O7: =M7-N7 -> 0 | P7: =SUMIFS(Registro!$H$2:$H$1001,Cálculo!$A$2:$A$1001,K$5,Cálculo!$C$2:$C$1001,$B$3*100+$A7) -> 0 | Q7: =SUMIFS(Cálculo!$K$2:$K$1001,Cálculo!$A$2:$A$1001,K$5,Cálculo!$C$2:$C$1001,$B$3*100+$A7)+SUMIFS(Cálculo!$L$2:$L$1001,Cálculo!$A$2:$A$1001,K$5,Cálculo!$C$2:$C$1001,$B$3*100+$A7) -> 0 | R7: =SUMIFS(Cálculo!$N$2:$N$1001,Cálculo!$A$2:$A$1001,K$5,Cálculo!$C$2:$C$1001,$B$3*100+$A7) -> 0 | S7: =COUNTIFS(Cálculo!$A$2:$A$1001,S$5,Cálculo!$C$2:$C$1001,$B$3*100+$A7) -> 0 | T7: =SUMIFS(Cálculo!$D$2:$D$1001,Cálculo!$A$2:$A$1001,S$5,Cálculo!$C$2:$C$1001,$B$3*100+$A7)+SUMIFS(Cálculo!$H$2:$H$1001,Cálculo!$A$2:$A$1001,S$5,Cálculo!$C$2:$C$1001,$B$3*100+$A7) -> 0 | U7: =SUMIFS(Cálculo!$E$2:$E$1001,Cálculo!$A$2:$A$1001,S$5,Cálculo!$C$2:$C$1001,$B$3*100+$A7) -> 0 | V7: =SUMIFS(Cálculo!$F$2:$F$1001,Cálculo!$A$2:$A$1001,S$5,Cálculo!$C$2:$C$1001,$B$3*100+$A7) -> 0 | W7: =U7-V7 -> 0 | X7: =SUMIFS(Registro!$H$2:$H$1001,Cálculo!$A$2:$A$1001,S$5,Cálculo!$C$2:$C$1001,$B$3*100+$A7) -> 0 | Y7: =SUMIFS(Cálculo!$K$2:$K$1001,Cálculo!$A$2:$A$1001,S$5,Cálculo!$C$2:$C$1001,$B$3*100+$A7)+SUMIFS(Cálculo!$L$2:$L$1001,Cálculo!$A$2:$A$1001,S$5,Cálculo!$C$2:$C$1001,$B$3*100+$A7) -> 0 | Z7: =SUMIFS(Cálculo!$N$2:$N$1001,Cálculo!$A$2:$A$1001,S$5,Cálculo!$C$2:$C$1001,$B$3*100+$A7) -> 0 | AA7: =C7+K7+S7 -> 0 | AB7: =E7+M7+U7 -> 0 | AC7: =F7+N7+V7 -> 0 | AD7: =G7+O7+W7 -> 0 | AE7: =H7+P7+X7 -> 0 | AF7: =J7+R7+Z7 -> 0
A8: 2 | B8: Febrero | C8: =COUNTIFS(Cálculo!$A$2:$A$1001,C$5,Cálculo!$C$2:$C$1001,$B$3*100+$A8) -> 0 | D8: =SUMIFS(Cálculo!$D$2:$D$1001,Cálculo!$A$2:$A$1001,C$5,Cálculo!$C$2:$C$1001,$B$3*100+$A8)+SUMIFS(Cálculo!$H$2:$H$1001,Cálculo!$A$2:$A$1001,C$5,Cálculo!$C$2:$C$1001,$B$3*100+$A8) -> 0 | E8: =SUMIFS(Cálculo!$E$2:$E$1001,Cálculo!$A$2:$A$1001,C$5,Cálculo!$C$2:$C$1001,$B$3*100+$A8) -> 0 | F8: =SUMIFS(Cálculo!$F$2:$F$1001,Cálculo!$A$2:$A$1001,C$5,Cálculo!$C$2:$C$1001,$B$3*100+$A8) -> 0 | G8: =E8-F8 -> 0 | H8: =SUMIFS(Registro!$H$2:$H$1001,Cálculo!$A$2:$A$1001,C$5,Cálculo!$C$2:$C$1001,$B$3*100+$A8) -> 0 | I8: =SUMIFS(Cálculo!$K$2:$K$1001,Cálculo!$A$2:$A$1001,C$5,Cálculo!$C$2:$C$1001,$B$3*100+$A8)+SUMIFS(Cálculo!$L$2:$L$1001,Cálculo!$A$2:$A$1001,C$5,Cálculo!$C$2:$C$1001,$B$3*100+$A8) -> 0 | J8: =SUMIFS(Cálculo!$N$2:$N$1001,Cálculo!$A$2:$A$1001,C$5,Cálculo!$C$2:$C$1001,$B$3*100+$A8) -> 0 | K8: =COUNTIFS(Cálculo!$A$2:$A$1001,K$5,Cálculo!$C$2:$C$1001,$B$3*100+$A8) -> 0 | L8: =SUMIFS(Cálculo!$D$2:$D$1001,Cálculo!$A$2:$A$1001,K$5,Cálculo!$C$2:$C$1001,$B$3*100+$A8)+SUMIFS(Cálculo!$H$2:$H$1001,Cálculo!$A$2:$A$1001,K$5,Cálculo!$C$2:$C$1001,$B$3*100+$A8) -> 0 | M8: =SUMIFS(Cálculo!$E$2:$E$1001,Cálculo!$A$2:$A$1001,K$5,Cálculo!$C$2:$C$1001,$B$3*100+$A8) -> 0 | N8: =SUMIFS(Cálculo!$F$2:$F$1001,Cálculo!$A$2:$A$1001,K$5,Cálculo!$C$2:$C$1001,$B$3*100+$A8) -> 0 | O8: =M8-N8 -> 0 | P8: =SUMIFS(Registro!$H$2:$H$1001,Cálculo!$A$2:$A$1001,K$5,Cálculo!$C$2:$C$1001,$B$3*100+$A8) -> 0 | Q8: =SUMIFS(Cálculo!$K$2:$K$1001,Cálculo!$A$2:$A$1001,K$5,Cálculo!$C$2:$C$1001,$B$3*100+$A8)+SUMIFS(Cálculo!$L$2:$L$1001,Cálculo!$A$2:$A$1001,K$5,Cálculo!$C$2:$C$1001,$B$3*100+$A8) -> 0 | R8: =SUMIFS(Cálculo!$N$2:$N$1001,Cálculo!$A$2:$A$1001,K$5,Cálculo!$C$2:$C$1001,$B$3*100+$A8) -> 0 | S8: =COUNTIFS(Cálculo!$A$2:$A$1001,S$5,Cálculo!$C$2:$C$1001,$B$3*100+$A8) -> 0 | T8: =SUMIFS(Cálculo!$D$2:$D$1001,Cálculo!$A$2:$A$1001,S$5,Cálculo!$C$2:$C$1001,$B$3*100+$A8)+SUMIFS(Cálculo!$H$2:$H$1001,Cálculo!$A$2:$A$1001,S$5,Cálculo!$C$2:$C$1001,$B$3*100+$A8) -> 0 | U8: =SUMIFS(Cálculo!$E$2:$E$1001,Cálculo!$A$2:$A$1001,S$5,Cálculo!$C$2:$C$1001,$B$3*100+$A8) -> 0 | V8: =SUMIFS(Cálculo!$F$2:$F$1001,Cálculo!$A$2:$A$1001,S$5,Cálculo!$C$2:$C$1001,$B$3*100+$A8) -> 0 | W8: =U8-V8 -> 0 | X8: =SUMIFS(Registro!$H$2:$H$1001,Cálculo!$A$2:$A$1001,S$5,Cálculo!$C$2:$C$1001,$B$3*100+$A8) -> 0 | Y8: =SUMIFS(Cálculo!$K$2:$K$1001,Cálculo!$A$2:$A$1001,S$5,Cálculo!$C$2:$C$1001,$B$3*100+$A8)+SUMIFS(Cálculo!$L$2:$L$1001,Cálculo!$A$2:$A$1001,S$5,Cálculo!$C$2:$C$1001,$B$3*100+$A8) -> 0 | Z8: =SUMIFS(Cálculo!$N$2:$N$1001,Cálculo!$A$2:$A$1001,S$5,Cálculo!$C$2:$C$1001,$B$3*100+$A8) -> 0 | AA8: =C8+K8+S8 -> 0 | AB8: =E8+M8+U8 -> 0 | AC8: =F8+N8+V8 -> 0 | AD8: =G8+O8+W8 -> 0 | AE8: =H8+P8+X8 -> 0 | AF8: =J8+R8+Z8 -> 0
A9: 3 | B9: Marzo | C9: =COUNTIFS(Cálculo!$A$2:$A$1001,C$5,Cálculo!$C$2:$C$1001,$B$3*100+$A9) -> 0 | D9: =SUMIFS(Cálculo!$D$2:$D$1001,Cálculo!$A$2:$A$1001,C$5,Cálculo!$C$2:$C$1001,$B$3*100+$A9)+SUMIFS(Cálculo!$H$2:$H$1001,Cálculo!$A$2:$A$1001,C$5,Cálculo!$C$2:$C$1001,$B$3*100+$A9) -> 0 | E9: =SUMIFS(Cálculo!$E$2:$E$1001,Cálculo!$A$2:$A$1001,C$5,Cálculo!$C$2:$C$1001,$B$3*100+$A9) -> 0 | F9: =SUMIFS(Cálculo!$F$2:$F$1001,Cálculo!$A$2:$A$1001,C$5,Cálculo!$C$2:$C$1001,$B$3*100+$A9) -> 0 | G9: =E9-F9 -> 0 | H9: =SUMIFS(Registro!$H$2:$H$1001,Cálculo!$A$2:$A$1001,C$5,Cálculo!$C$2:$C$1001,$B$3*100+$A9) -> 0 | I9: =SUMIFS(Cálculo!$K$2:$K$1001,Cálculo!$A$2:$A$1001,C$5,Cálculo!$C$2:$C$1001,$B$3*100+$A9)+SUMIFS(Cálculo!$L$2:$L$1001,Cálculo!$A$2:$A$1001,C$5,Cálculo!$C$2:$C$1001,$B$3*100+$A9) -> 0 | J9: =SUMIFS(Cálculo!$N$2:$N$1001,Cálculo!$A$2:$A$1001,C$5,Cálculo!$C$2:$C$1001,$B$3*100+$A9) -> 0 | K9: =COUNTIFS(Cálculo!$A$2:$A$1001,K$5,Cálculo!$C$2:$C$1001,$B$3*100+$A9) -> 0 | L9: =SUMIFS(Cálculo!$D$2:$D$1001,Cálculo!$A$2:$A$1001,K$5,Cálculo!$C$2:$C$1001,$B$3*100+$A9)+SUMIFS(Cálculo!$H$2:$H$1001,Cálculo!$A$2:$A$1001,K$5,Cálculo!$C$2:$C$1001,$B$3*100+$A9) -> 0 | M9: =SUMIFS(Cálculo!$E$2:$E$1001,Cálculo!$A$2:$A$1001,K$5,Cálculo!$C$2:$C$1001,$B$3*100+$A9) -> 0 | N9: =SUMIFS(Cálculo!$F$2:$F$1001,Cálculo!$A$2:$A$1001,K$5,Cálculo!$C$2:$C$1001,$B$3*100+$A9) -> 0 | O9: =M9-N9 -> 0 | P9: =SUMIFS(Registro!$H$2:$H$1001,Cálculo!$A$2:$A$1001,K$5,Cálculo!$C$2:$C$1001,$B$3*100+$A9) -> 0 | Q9: =SUMIFS(Cálculo!$K$2:$K$1001,Cálculo!$A$2:$A$1001,K$5,Cálculo!$C$2:$C$1001,$B$3*100+$A9)+SUMIFS(Cálculo!$L$2:$L$1001,Cálculo!$A$2:$A$1001,K$5,Cálculo!$C$2:$C$1001,$B$3*100+$A9) -> 0 | R9: =SUMIFS(Cálculo!$N$2:$N$1001,Cálculo!$A$2:$A$1001,K$5,Cálculo!$C$2:$C$1001,$B$3*100+$A9) -> 0 | S9: =COUNTIFS(Cálculo!$A$2:$A$1001,S$5,Cálculo!$C$2:$C$1001,$B$3*100+$A9) -> 0 | T9: =SUMIFS(Cálculo!$D$2:$D$1001,Cálculo!$A$2:$A$1001,S$5,Cálculo!$C$2:$C$1001,$B$3*100+$A9)+SUMIFS(Cálculo!$H$2:$H$1001,Cálculo!$A$2:$A$1001,S$5,Cálculo!$C$2:$C$1001,$B$3*100+$A9) -> 0 | U9: =SUMIFS(Cálculo!$E$2:$E$1001,Cálculo!$A$2:$A$1001,S$5,Cálculo!$C$2:$C$1001,$B$3*100+$A9) -> 0 | V9: =SUMIFS(Cálculo!$F$2:$F$1001,Cálculo!$A$2:$A$1001,S$5,Cálculo!$C$2:$C$1001,$B$3*100+$A9) -> 0 | W9: =U9-V9 -> 0 | X9: =SUMIFS(Registro!$H$2:$H$1001,Cálculo!$A$2:$A$1001,S$5,Cálculo!$C$2:$C$1001,$B$3*100+$A9) -> 0 | Y9: =SUMIFS(Cálculo!$K$2:$K$1001,Cálculo!$A$2:$A$1001,S$5,Cálculo!$C$2:$C$1001,$B$3*100+$A9)+SUMIFS(Cálculo!$L$2:$L$1001,Cálculo!$A$2:$A$1001,S$5,Cálculo!$C$2:$C$1001,$B$3*100+$A9) -> 0 | Z9: =SUMIFS(Cálculo!$N$2:$N$1001,Cálculo!$A$2:$A$1001,S$5,Cálculo!$C$2:$C$1001,$B$3*100+$A9) -> 0 | AA9: =C9+K9+S9 -> 0 | AB9: =E9+M9+U9 -> 0 | AC9: =F9+N9+V9 -> 0 | AD9: =G9+O9+W9 -> 0 | AE9: =H9+P9+X9 -> 0 | AF9: =J9+R9+Z9 -> 0
A10: 4 | B10: Abril | C10: =COUNTIFS(Cálculo!$A$2:$A$1001,C$5,Cálculo!$C$2:$C$1001,$B$3*100+$A10) -> 0 | D10: =SUMIFS(Cálculo!$D$2:$D$1001,Cálculo!$A$2:$A$1001,C$5,Cálculo!$C$2:$C$1001,$B$3*100+$A10)+SUMIFS(Cálculo!$H$2:$H$1001,Cálculo!$A$2:$A$1001,C$5,Cálculo!$C$2:$C$1001,$B$3*100+$A10) -> 0 | E10: =SUMIFS(Cálculo!$E$2:$E$1001,Cálculo!$A$2:$A$1001,C$5,Cálculo!$C$2:$C$1001,$B$3*100+$A10) -> 0 | F10: =SUMIFS(Cálculo!$F$2:$F$1001,Cálculo!$A$2:$A$1001,C$5,Cálculo!$C$2:$C$1001,$B$3*100+$A10) -> 0 | G10: =E10-F10 -> 0 | H10: =SUMIFS(Registro!$H$2:$H$1001,Cálculo!$A$2:$A$1001,C$5,Cálculo!$C$2:$C$1001,$B$3*100+$A10) -> 0 | I10: =SUMIFS(Cálculo!$K$2:$K$1001,Cálculo!$A$2:$A$1001,C$5,Cálculo!$C$2:$C$1001,$B$3*100+$A10)+SUMIFS(Cálculo!$L$2:$L$1001,Cálculo!$A$2:$A$1001,C$5,Cálculo!$C$2:$C$1001,$B$3*100+$A10) -> 0 | J10: =SUMIFS(Cálculo!$N$2:$N$1001,Cálculo!$A$2:$A$1001,C$5,Cálculo!$C$2:$C$1001,$B$3*100+$A10) -> 0 | K10: =COUNTIFS(Cálculo!$A$2:$A$1001,K$5,Cálculo!$C$2:$C$1001,$B$3*100+$A10) -> 0 | L10: =SUMIFS(Cálculo!$D$2:$D$1001,Cálculo!$A$2:$A$1001,K$5,Cálculo!$C$2:$C$1001,$B$3*100+$A10)+SUMIFS(Cálculo!$H$2:$H$1001,Cálculo!$A$2:$A$1001,K$5,Cálculo!$C$2:$C$1001,$B$3*100+$A10) -> 0 | M10: =SUMIFS(Cálculo!$E$2:$E$1001,Cálculo!$A$2:$A$1001,K$5,Cálculo!$C$2:$C$1001,$B$3*100+$A10) -> 0 | N10: =SUMIFS(Cálculo!$F$2:$F$1001,Cálculo!$A$2:$A$1001,K$5,Cálculo!$C$2:$C$1001,$B$3*100+$A10) -> 0 | O10: =M10-N10 -> 0 | P10: =SUMIFS(Registro!$H$2:$H$1001,Cálculo!$A$2:$A$1001,K$5,Cálculo!$C$2:$C$1001,$B$3*100+$A10) -> 0 | Q10: =SUMIFS(Cálculo!$K$2:$K$1001,Cálculo!$A$2:$A$1001,K$5,Cálculo!$C$2:$C$1001,$B$3*100+$A10)+SUMIFS(Cálculo!$L$2:$L$1001,Cálculo!$A$2:$A$1001,K$5,Cálculo!$C$2:$C$1001,$B$3*100+$A10) -> 0 | R10: =SUMIFS(Cálculo!$N$2:$N$1001,Cálculo!$A$2:$A$1001,K$5,Cálculo!$C$2:$C$1001,$B$3*100+$A10) -> 0 | S10: =COUNTIFS(Cálculo!$A$2:$A$1001,S$5,Cálculo!$C$2:$C$1001,$B$3*100+$A10) -> 0 | T10: =SUMIFS(Cálculo!$D$2:$D$1001,Cálculo!$A$2:$A$1001,S$5,Cálculo!$C$2:$C$1001,$B$3*100+$A10)+SUMIFS(Cálculo!$H$2:$H$1001,Cálculo!$A$2:$A$1001,S$5,Cálculo!$C$2:$C$1001,$B$3*100+$A10) -> 0 | U10: =SUMIFS(Cálculo!$E$2:$E$1001,Cálculo!$A$2:$A$1001,S$5,Cálculo!$C$2:$C$1001,$B$3*100+$A10) -> 0 | V10: =SUMIFS(Cálculo!$F$2:$F$1001,Cálculo!$A$2:$A$1001,S$5,Cálculo!$C$2:$C$1001,$B$3*100+$A10) -> 0 | W10: =U10-V10 -> 0 | X10: =SUMIFS(Registro!$H$2:$H$1001,Cálculo!$A$2:$A$1001,S$5,Cálculo!$C$2:$C$1001,$B$3*100+$A10) -> 0 | Y10: =SUMIFS(Cálculo!$K$2:$K$1001,Cálculo!$A$2:$A$1001,S$5,Cálculo!$C$2:$C$1001,$B$3*100+$A10)+SUMIFS(Cálculo!$L$2:$L$1001,Cálculo!$A$2:$A$1001,S$5,Cálculo!$C$2:$C$1001,$B$3*100+$A10) -> 0 | Z10: =SUMIFS(Cálculo!$N$2:$N$1001,Cálculo!$A$2:$A$1001,S$5,Cálculo!$C$2:$C$1001,$B$3*100+$A10) -> 0 | AA10: =C10+K10+S10 -> 0 | AB10: =E10+M10+U10 -> 0 | AC10: =F10+N10+V10 -> 0 | AD10: =G10+O10+W10 -> 0 | AE10: =H10+P10+X10 -> 0 | AF10: =J10+R10+Z10 -> 0
A11: 5 | B11: Mayo | C11: =COUNTIFS(Cálculo!$A$2:$A$1001,C$5,Cálculo!$C$2:$C$1001,$B$3*100+$A11) -> 0 | D11: =SUMIFS(Cálculo!$D$2:$D$1001,Cálculo!$A$2:$A$1001,C$5,Cálculo!$C$2:$C$1001,$B$3*100+$A11)+SUMIFS(Cálculo!$H$2:$H$1001,Cálculo!$A$2:$A$1001,C$5,Cálculo!$C$2:$C$1001,$B$3*100+$A11) -> 0 | E11: =SUMIFS(Cálculo!$E$2:$E$1001,Cálculo!$A$2:$A$1001,C$5,Cálculo!$C$2:$C$1001,$B$3*100+$A11) -> 0 | F11: =SUMIFS(Cálculo!$F$2:$F$1001,Cálculo!$A$2:$A$1001,C$5,Cálculo!$C$2:$C$1001,$B$3*100+$A11) -> 0 | G11: =E11-F11 -> 0 | H11: =SUMIFS(Registro!$H$2:$H$1001,Cálculo!$A$2:$A$1001,C$5,Cálculo!$C$2:$C$1001,$B$3*100+$A11) -> 0 | I11: =SUMIFS(Cálculo!$K$2:$K$1001,Cálculo!$A$2:$A$1001,C$5,Cálculo!$C$2:$C$1001,$B$3*100+$A11)+SUMIFS(Cálculo!$L$2:$L$1001,Cálculo!$A$2:$A$1001,C$5,Cálculo!$C$2:$C$1001,$B$3*100+$A11) -> 0 | J11: =SUMIFS(Cálculo!$N$2:$N$1001,Cálculo!$A$2:$A$1001,C$5,Cálculo!$C$2:$C$1001,$B$3*100+$A11) -> 0 | K11: =COUNTIFS(Cálculo!$A$2:$A$1001,K$5,Cálculo!$C$2:$C$1001,$B$3*100+$A11) -> 0 | L11: =SUMIFS(Cálculo!$D$2:$D$1001,Cálculo!$A$2:$A$1001,K$5,Cálculo!$C$2:$C$1001,$B$3*100+$A11)+SUMIFS(Cálculo!$H$2:$H$1001,Cálculo!$A$2:$A$1001,K$5,Cálculo!$C$2:$C$1001,$B$3*100+$A11) -> 0 | M11: =SUMIFS(Cálculo!$E$2:$E$1001,Cálculo!$A$2:$A$1001,K$5,Cálculo!$C$2:$C$1001,$B$3*100+$A11) -> 0 | N11: =SUMIFS(Cálculo!$F$2:$F$1001,Cálculo!$A$2:$A$1001,K$5,Cálculo!$C$2:$C$1001,$B$3*100+$A11) -> 0 | O11: =M11-N11 -> 0 | P11: =SUMIFS(Registro!$H$2:$H$1001,Cálculo!$A$2:$A$1001,K$5,Cálculo!$C$2:$C$1001,$B$3*100+$A11) -> 0 | Q11: =SUMIFS(Cálculo!$K$2:$K$1001,Cálculo!$A$2:$A$1001,K$5,Cálculo!$C$2:$C$1001,$B$3*100+$A11)+SUMIFS(Cálculo!$L$2:$L$1001,Cálculo!$A$2:$A$1001,K$5,Cálculo!$C$2:$C$1001,$B$3*100+$A11) -> 0 | R11: =SUMIFS(Cálculo!$N$2:$N$1001,Cálculo!$A$2:$A$1001,K$5,Cálculo!$C$2:$C$1001,$B$3*100+$A11) -> 0 | S11: =COUNTIFS(Cálculo!$A$2:$A$1001,S$5,Cálculo!$C$2:$C$1001,$B$3*100+$A11) -> 0 | T11: =SUMIFS(Cálculo!$D$2:$D$1001,Cálculo!$A$2:$A$1001,S$5,Cálculo!$C$2:$C$1001,$B$3*100+$A11)+SUMIFS(Cálculo!$H$2:$H$1001,Cálculo!$A$2:$A$1001,S$5,Cálculo!$C$2:$C$1001,$B$3*100+$A11) -> 0 | U11: =SUMIFS(Cálculo!$E$2:$E$1001,Cálculo!$A$2:$A$1001,S$5,Cálculo!$C$2:$C$1001,$B$3*100+$A11) -> 0 | V11: =SUMIFS(Cálculo!$F$2:$F$1001,Cálculo!$A$2:$A$1001,S$5,Cálculo!$C$2:$C$1001,$B$3*100+$A11) -> 0 | W11: =U11-V11 -> 0 | X11: =SUMIFS(Registro!$H$2:$H$1001,Cálculo!$A$2:$A$1001,S$5,Cálculo!$C$2:$C$1001,$B$3*100+$A11) -> 0 | Y11: =SUMIFS(Cálculo!$K$2:$K$1001,Cálculo!$A$2:$A$1001,S$5,Cálculo!$C$2:$C$1001,$B$3*100+$A11)+SUMIFS(Cálculo!$L$2:$L$1001,Cálculo!$A$2:$A$1001,S$5,Cálculo!$C$2:$C$1001,$B$3*100+$A11) -> 0 | Z11: =SUMIFS(Cálculo!$N$2:$N$1001,Cálculo!$A$2:$A$1001,S$5,Cálculo!$C$2:$C$1001,$B$3*100+$A11) -> 0 | AA11: =C11+K11+S11 -> 0 | AB11: =E11+M11+U11 -> 0 | AC11: =F11+N11+V11 -> 0 | AD11: =G11+O11+W11 -> 0 | AE11: =H11+P11+X11 -> 0 | AF11: =J11+R11+Z11 -> 0
A12: 6 | B12: Junio | C12: =COUNTIFS(Cálculo!$A$2:$A$1001,C$5,Cálculo!$C$2:$C$1001,$B$3*100+$A12) -> 0 | D12: =SUMIFS(Cálculo!$D$2:$D$1001,Cálculo!$A$2:$A$1001,C$5,Cálculo!$C$2:$C$1001,$B$3*100+$A12)+SUMIFS(Cálculo!$H$2:$H$1001,Cálculo!$A$2:$A$1001,C$5,Cálculo!$C$2:$C$1001,$B$3*100+$A12) -> 0 | E12: =SUMIFS(Cálculo!$E$2:$E$1001,Cálculo!$A$2:$A$1001,C$5,Cálculo!$C$2:$C$1001,$B$3*100+$A12) -> 0 | F12: =SUMIFS(Cálculo!$F$2:$F$1001,Cálculo!$A$2:$A$1001,C$5,Cálculo!$C$2:$C$1001,$B$3*100+$A12) -> 0 | G12: =E12-F12 -> 0 | H12: =SUMIFS(Registro!$H$2:$H$1001,Cálculo!$A$2:$A$1001,C$5,Cálculo!$C$2:$C$1001,$B$3*100+$A12) -> 0 | I12: =SUMIFS(Cálculo!$K$2:$K$1001,Cálculo!$A$2:$A$1001,C$5,Cálculo!$C$2:$C$1001,$B$3*100+$A12)+SUMIFS(Cálculo!$L$2:$L$1001,Cálculo!$A$2:$A$1001,C$5,Cálculo!$C$2:$C$1001,$B$3*100+$A12) -> 0 | J12: =SUMIFS(Cálculo!$N$2:$N$1001,Cálculo!$A$2:$A$1001,C$5,Cálculo!$C$2:$C$1001,$B$3*100+$A12) -> 0 | K12: =COUNTIFS(Cálculo!$A$2:$A$1001,K$5,Cálculo!$C$2:$C$1001,$B$3*100+$A12) -> 0 | L12: =SUMIFS(Cálculo!$D$2:$D$1001,Cálculo!$A$2:$A$1001,K$5,Cálculo!$C$2:$C$1001,$B$3*100+$A12)+SUMIFS(Cálculo!$H$2:$H$1001,Cálculo!$A$2:$A$1001,K$5,Cálculo!$C$2:$C$1001,$B$3*100+$A12) -> 0 | M12: =SUMIFS(Cálculo!$E$2:$E$1001,Cálculo!$A$2:$A$1001,K$5,Cálculo!$C$2:$C$1001,$B$3*100+$A12) -> 0 | N12: =SUMIFS(Cálculo!$F$2:$F$1001,Cálculo!$A$2:$A$1001,K$5,Cálculo!$C$2:$C$1001,$B$3*100+$A12) -> 0 | O12: =M12-N12 -> 0 | P12: =SUMIFS(Registro!$H$2:$H$1001,Cálculo!$A$2:$A$1001,K$5,Cálculo!$C$2:$C$1001,$B$3*100+$A12) -> 0 | Q12: =SUMIFS(Cálculo!$K$2:$K$1001,Cálculo!$A$2:$A$1001,K$5,Cálculo!$C$2:$C$1001,$B$3*100+$A12)+SUMIFS(Cálculo!$L$2:$L$1001,Cálculo!$A$2:$A$1001,K$5,Cálculo!$C$2:$C$1001,$B$3*100+$A12) -> 0 | R12: =SUMIFS(Cálculo!$N$2:$N$1001,Cálculo!$A$2:$A$1001,K$5,Cálculo!$C$2:$C$1001,$B$3*100+$A12) -> 0 | S12: =COUNTIFS(Cálculo!$A$2:$A$1001,S$5,Cálculo!$C$2:$C$1001,$B$3*100+$A12) -> 0 | T12: =SUMIFS(Cálculo!$D$2:$D$1001,Cálculo!$A$2:$A$1001,S$5,Cálculo!$C$2:$C$1001,$B$3*100+$A12)+SUMIFS(Cálculo!$H$2:$H$1001,Cálculo!$A$2:$A$1001,S$5,Cálculo!$C$2:$C$1001,$B$3*100+$A12) -> 0 | U12: =SUMIFS(Cálculo!$E$2:$E$1001,Cálculo!$A$2:$A$1001,S$5,Cálculo!$C$2:$C$1001,$B$3*100+$A12) -> 0 | V12: =SUMIFS(Cálculo!$F$2:$F$1001,Cálculo!$A$2:$A$1001,S$5,Cálculo!$C$2:$C$1001,$B$3*100+$A12) -> 0 | W12: =U12-V12 -> 0 | X12: =SUMIFS(Registro!$H$2:$H$1001,Cálculo!$A$2:$A$1001,S$5,Cálculo!$C$2:$C$1001,$B$3*100+$A12) -> 0 | Y12: =SUMIFS(Cálculo!$K$2:$K$1001,Cálculo!$A$2:$A$1001,S$5,Cálculo!$C$2:$C$1001,$B$3*100+$A12)+SUMIFS(Cálculo!$L$2:$L$1001,Cálculo!$A$2:$A$1001,S$5,Cálculo!$C$2:$C$1001,$B$3*100+$A12) -> 0 | Z12: =SUMIFS(Cálculo!$N$2:$N$1001,Cálculo!$A$2:$A$1001,S$5,Cálculo!$C$2:$C$1001,$B$3*100+$A12) -> 0 | AA12: =C12+K12+S12 -> 0 | AB12: =E12+M12+U12 -> 0 | AC12: =F12+N12+V12 -> 0 | AD12: =G12+O12+W12 -> 0 | AE12: =H12+P12+X12 -> 0 | AF12: =J12+R12+Z12 -> 0
A13: 7 | B13: Julio | C13: =COUNTIFS(Cálculo!$A$2:$A$1001,C$5,Cálculo!$C$2:$C$1001,$B$3*100+$A13) -> 0 | D13: =SUMIFS(Cálculo!$D$2:$D$1001,Cálculo!$A$2:$A$1001,C$5,Cálculo!$C$2:$C$1001,$B$3*100+$A13)+SUMIFS(Cálculo!$H$2:$H$1001,Cálculo!$A$2:$A$1001,C$5,Cálculo!$C$2:$C$1001,$B$3*100+$A13) -> 0 | E13: =SUMIFS(Cálculo!$E$2:$E$1001,Cálculo!$A$2:$A$1001,C$5,Cálculo!$C$2:$C$1001,$B$3*100+$A13) -> 0 | F13: =SUMIFS(Cálculo!$F$2:$F$1001,Cálculo!$A$2:$A$1001,C$5,Cálculo!$C$2:$C$1001,$B$3*100+$A13) -> 0 | G13: =E13-F13 -> 0 | H13: =SUMIFS(Registro!$H$2:$H$1001,Cálculo!$A$2:$A$1001,C$5,Cálculo!$C$2:$C$1001,$B$3*100+$A13) -> 0 | I13: =SUMIFS(Cálculo!$K$2:$K$1001,Cálculo!$A$2:$A$1001,C$5,Cálculo!$C$2:$C$1001,$B$3*100+$A13)+SUMIFS(Cálculo!$L$2:$L$1001,Cálculo!$A$2:$A$1001,C$5,Cálculo!$C$2:$C$1001,$B$3*100+$A13) -> 0 | J13: =SUMIFS(Cálculo!$N$2:$N$1001,Cálculo!$A$2:$A$1001,C$5,Cálculo!$C$2:$C$1001,$B$3*100+$A13) -> 0 | K13: =COUNTIFS(Cálculo!$A$2:$A$1001,K$5,Cálculo!$C$2:$C$1001,$B$3*100+$A13) -> 0 | L13: =SUMIFS(Cálculo!$D$2:$D$1001,Cálculo!$A$2:$A$1001,K$5,Cálculo!$C$2:$C$1001,$B$3*100+$A13)+SUMIFS(Cálculo!$H$2:$H$1001,Cálculo!$A$2:$A$1001,K$5,Cálculo!$C$2:$C$1001,$B$3*100+$A13) -> 0 | M13: =SUMIFS(Cálculo!$E$2:$E$1001,Cálculo!$A$2:$A$1001,K$5,Cálculo!$C$2:$C$1001,$B$3*100+$A13) -> 0 | N13: =SUMIFS(Cálculo!$F$2:$F$1001,Cálculo!$A$2:$A$1001,K$5,Cálculo!$C$2:$C$1001,$B$3*100+$A13) -> 0 | O13: =M13-N13 -> 0 | P13: =SUMIFS(Registro!$H$2:$H$1001,Cálculo!$A$2:$A$1001,K$5,Cálculo!$C$2:$C$1001,$B$3*100+$A13) -> 0 | Q13: =SUMIFS(Cálculo!$K$2:$K$1001,Cálculo!$A$2:$A$1001,K$5,Cálculo!$C$2:$C$1001,$B$3*100+$A13)+SUMIFS(Cálculo!$L$2:$L$1001,Cálculo!$A$2:$A$1001,K$5,Cálculo!$C$2:$C$1001,$B$3*100+$A13) -> 0 | R13: =SUMIFS(Cálculo!$N$2:$N$1001,Cálculo!$A$2:$A$1001,K$5,Cálculo!$C$2:$C$1001,$B$3*100+$A13) -> 0 | S13: =COUNTIFS(Cálculo!$A$2:$A$1001,S$5,Cálculo!$C$2:$C$1001,$B$3*100+$A13) -> 0 | T13: =SUMIFS(Cálculo!$D$2:$D$1001,Cálculo!$A$2:$A$1001,S$5,Cálculo!$C$2:$C$1001,$B$3*100+$A13)+SUMIFS(Cálculo!$H$2:$H$1001,Cálculo!$A$2:$A$1001,S$5,Cálculo!$C$2:$C$1001,$B$3*100+$A13) -> 0 | U13: =SUMIFS(Cálculo!$E$2:$E$1001,Cálculo!$A$2:$A$1001,S$5,Cálculo!$C$2:$C$1001,$B$3*100+$A13) -> 0 | V13: =SUMIFS(Cálculo!$F$2:$F$1001,Cálculo!$A$2:$A$1001,S$5,Cálculo!$C$2:$C$1001,$B$3*100+$A13) -> 0 | W13: =U13-V13 -> 0 | X13: =SUMIFS(Registro!$H$2:$H$1001,Cálculo!$A$2:$A$1001,S$5,Cálculo!$C$2:$C$1001,$B$3*100+$A13) -> 0 | Y13: =SUMIFS(Cálculo!$K$2:$K$1001,Cálculo!$A$2:$A$1001,S$5,Cálculo!$C$2:$C$1001,$B$3*100+$A13)+SUMIFS(Cálculo!$L$2:$L$1001,Cálculo!$A$2:$A$1001,S$5,Cálculo!$C$2:$C$1001,$B$3*100+$A13) -> 0 | Z13: =SUMIFS(Cálculo!$N$2:$N$1001,Cálculo!$A$2:$A$1001,S$5,Cálculo!$C$2:$C$1001,$B$3*100+$A13) -> 0 | AA13: =C13+K13+S13 -> 0 | AB13: =E13+M13+U13 -> 0 | AC13: =F13+N13+V13 -> 0 | AD13: =G13+O13+W13 -> 0 | AE13: =H13+P13+X13 -> 0 | AF13: =J13+R13+Z13 -> 0
